Workbook

Sheet 개요
B1: ㈜오리온 | FDD 조정 DCF 가치평가 | C1: ㈜오리온 | DCF 가치평가 | D1: ㈜오리온 | DCF 가치평가 | E1: ㈜오리온 | DCF 가치평가 | F1: ㈜오리온 | DCF 가치평가 | G1: ㈜오리온 | DCF 가치평가 | H1: ㈜오리온 | DCF 가치평가
B2: ㈜오리온 | DCF 가치평가 | C2: ㈜오리온 | DCF 가치평가 | D2: ㈜오리온 | DCF 가치평가 | E2: ㈜오리온 | DCF 가치평가 | F2: ㈜오리온 | DCF 가치평가 | G2: ㈜오리온 | DCF 가치평가 | H2: ㈜오리온 | DCF 가치평가
B4: 모델 개요 | C4: 값
B5: 회사명 | C5: ㈜오리온
B6: 종목코드 | C6: 271560
B7: 가치평가기준일 | C7: 46022
B8: 정보기준일 | C8: 46099
B9: 회계기준 | C9: K-IFRS 연결재무제표
B10: 통화 / 단위 | C10: 원화(KRW) 백만원, 주당 자료 제외
B11: 과거 실적기간 | C11: 2023A-2025A
B12: 추정기간 | C12: 2026E-2030E
B13: 가치평가방법 | C13: FCFF DCF / FDD QoE·순차입금·정상 NWC / 고든 성장모형
B14: 할인 기준 | C14: 연말 기준
B15: 작성자 | C15: 연한준
B16: 버전 | C16: v2.0 FDD Review
B18: 모델 흐름 | C18: 모델 흐름 | D18: 모델 흐름 | E18: 모델 흐름 | F18: 모델 흐름 | G18: 모델 흐름 | H18: 모델 흐름
B19: 공시 재무정보 → 영업추정 → FDD QoE·정상 NWC·Net Debt → FCFF → 기업가치 → FDD 지분가치 Bridge → 주당 내재가치 | C19: 공시 재무정보 → 지역별 매출액 추정 → 영업실적 추정 → NWC / Capex 명세 → FCFF → WACC / 계속기업가치 → 기업가치-지분가치 조정 → 주당 내재가치 | D19: 공시 재무정보 → 지역별 매출액 추정 → 영업실적 추정 → NWC / Capex 명세 → FCFF → WACC / 계속기업가치 → 기업가치-지분가치 조정 → 주당 내재가치 | E19: 공시 재무정보 → 지역별 매출액 추정 → 영업실적 추정 → NWC / Capex 명세 → FCFF → WACC / 계속기업가치 → 기업가치-지분가치 조정 → 주당 내재가치 | F19: 공시 재무정보 → 지역별 매출액 추정 → 영업실적 추정 → NWC / Capex 명세 → FCFF → WACC / 계속기업가치 → 기업가치-지분가치 조정 → 주당 내재가치 | G19: 공시 재무정보 → 지역별 매출액 추정 → 영업실적 추정 → NWC / Capex 명세 → FCFF → WACC / 계속기업가치 → 기업가치-지분가치 조정 → 주당 내재가치 | H19: 공시 재무정보 → 지역별 매출액 추정 → 영업실적 추정 → NWC / Capex 명세 → FCFF → WACC / 계속기업가치 → 기업가치-지분가치 조정 → 주당 내재가치
B20: 공시 재무정보 → 지역별 매출액 추정 → 영업실적 추정 → NWC / Capex 명세 → FCFF → WACC / 계속기업가치 → 기업가치-지분가치 조정 → 주당 내재가치 | C20: 공시 재무정보 → 지역별 매출액 추정 → 영업실적 추정 → NWC / Capex 명세 → FCFF → WACC / 계속기업가치 → 기업가치-지분가치 조정 → 주당 내재가치 | D20: 공시 재무정보 → 지역별 매출액 추정 → 영업실적 추정 → NWC / Capex 명세 → FCFF → WACC / 계속기업가치 → 기업가치-지분가치 조정 → 주당 내재가치 | E20: 공시 재무정보 → 지역별 매출액 추정 → 영업실적 추정 → NWC / Capex 명세 → FCFF → WACC / 계속기업가치 → 기업가치-지분가치 조정 → 주당 내재가치 | F20: 공시 재무정보 → 지역별 매출액 추정 → 영업실적 추정 → NWC / Capex 명세 → FCFF → WACC / 계속기업가치 → 기업가치-지분가치 조정 → 주당 내재가치 | G20: 공시 재무정보 → 지역별 매출액 추정 → 영업실적 추정 → NWC / Capex 명세 → FCFF → WACC / 계속기업가치 → 기업가치-지분가치 조정 → 주당 내재가치 | H20: 공시 재무정보 → 지역별 매출액 추정 → 영업실적 추정 → NWC / Capex 명세 → FCFF → WACC / 계속기업가치 → 기업가치-지분가치 조정 → 주당 내재가치
B21: 공시 재무정보 → 지역별 매출액 추정 → 영업실적 추정 → NWC / Capex 명세 → FCFF → WACC / 계속기업가치 → 기업가치-지분가치 조정 → 주당 내재가치 | C21: 공시 재무정보 → 지역별 매출액 추정 → 영업실적 추정 → NWC / Capex 명세 → FCFF → WACC / 계속기업가치 → 기업가치-지분가치 조정 → 주당 내재가치 | D21: 공시 재무정보 → 지역별 매출액 추정 → 영업실적 추정 → NWC / Capex 명세 → FCFF → WACC / 계속기업가치 → 기업가치-지분가치 조정 → 주당 내재가치 | E21: 공시 재무정보 → 지역별 매출액 추정 → 영업실적 추정 → NWC / Capex 명세 → FCFF → WACC / 계속기업가치 → 기업가치-지분가치 조정 → 주당 내재가치 | F21: 공시 재무정보 → 지역별 매출액 추정 → 영업실적 추정 → NWC / Capex 명세 → FCFF → WACC / 계속기업가치 → 기업가치-지분가치 조정 → 주당 내재가치 | G21: 공시 재무정보 → 지역별 매출액 추정 → 영업실적 추정 → NWC / Capex 명세 → FCFF → WACC / 계속기업가치 → 기업가치-지분가치 조정 → 주당 내재가치 | H21: 공시 재무정보 → 지역별 매출액 추정 → 영업실적 추정 → NWC / Capex 명세 → FCFF → WACC / 계속기업가치 → 기업가치-지분가치 조정 → 주당 내재가치
B23: 색상 규칙 | C23: 색상 규칙 | D23: 색상 규칙 | E23: 색상 규칙 | F23: 색상 규칙 | G23: 색상 규칙 | H23: 색상 규칙
B24: 파란색 글꼴 | C24: 수정 가능 가정 | E24: 중요한 한계: 가치평가기준일 이후 공시된 2025 회계연도 사업보고서를 이용한 교육용 가치평가입니다. 시장 관련 가정은 예시이며 실제 업무 적용 전 최신 시장자료로 갱신해야 합니다.
B25: 초록색 글꼴 | C25: 다른 시트 참조 | E25: 중요한 한계: 공개자료 기반 FDD입니다. 거래원장·월별 NWC·계약서·세무자료가 없어 미확인 항목은 0으로 두고 별도 입력칸과 잔여 확인사항으로 표시했습니다.
B26: 검은색 글꼴 | C26: 수식 / 계산
B27: 빨간색 글꼴 | C27: 경고 / 외부참조 표시
B29: 모델 상태는 요약 및 검증 시트에 표시됩니다. 파란색 글꼴의 입력값만 수정하면 모든 가치평가 결과가 자동으로 갱신됩니다. | C29: 모델 상태는 요약 및 검증 시트에 표시됩니다. 파란색 글꼴의 입력값만 수정하면 모든 가치평가 결과가 자동으로 갱신됩니다. | D29: 모델 상태는 요약 및 검증 시트에 표시됩니다. 파란색 글꼴의 입력값만 수정하면 모든 가치평가 결과가 자동으로 갱신됩니다. | E29: 모델 상태는 요약 및 검증 시트에 표시됩니다. 파란색 글꼴의 입력값만 수정하면 모든 가치평가 결과가 자동으로 갱신됩니다. | F29: 모델 상태는 요약 및 검증 시트에 표시됩니다. 파란색 글꼴의 입력값만 수정하면 모든 가치평가 결과가 자동으로 갱신됩니다. | G29: 모델 상태는 요약 및 검증 시트에 표시됩니다. 파란색 글꼴의 입력값만 수정하면 모든 가치평가 결과가 자동으로 갱신됩니다. | H29: 모델 상태는 요약 및 검증 시트에 표시됩니다. 파란색 글꼴의 입력값만 수정하면 모든 가치평가 결과가 자동으로 갱신됩니다.
B30: 모델 상태는 요약 및 검증 시트에 표시됩니다. 파란색 글꼴의 입력값만 수정하면 모든 가치평가 결과가 자동으로 갱신됩니다. | C30: 모델 상태는 요약 및 검증 시트에 표시됩니다. 파란색 글꼴의 입력값만 수정하면 모든 가치평가 결과가 자동으로 갱신됩니다. | D30: 모델 상태는 요약 및 검증 시트에 표시됩니다. 파란색 글꼴의 입력값만 수정하면 모든 가치평가 결과가 자동으로 갱신됩니다. | E30: 모델 상태는 요약 및 검증 시트에 표시됩니다. 파란색 글꼴의 입력값만 수정하면 모든 가치평가 결과가 자동으로 갱신됩니다. | F30: 모델 상태는 요약 및 검증 시트에 표시됩니다. 파란색 글꼴의 입력값만 수정하면 모든 가치평가 결과가 자동으로 갱신됩니다. | G30: 모델 상태는 요약 및 검증 시트에 표시됩니다. 파란색 글꼴의 입력값만 수정하면 모든 가치평가 결과가 자동으로 갱신됩니다. | H30: 모델 상태는 요약 및 검증 시트에 표시됩니다. 파란색 글꼴의 입력값만 수정하면 모든 가치평가 결과가 자동으로 갱신됩니다.
B31: 모델 상태는 요약 및 검증 시트에 표시됩니다. 파란색 글꼴의 입력값만 수정하면 모든 가치평가 결과가 자동으로 갱신됩니다. | C31: 모델 상태는 요약 및 검증 시트에 표시됩니다. 파란색 글꼴의 입력값만 수정하면 모든 가치평가 결과가 자동으로 갱신됩니다. | D31: 모델 상태는 요약 및 검증 시트에 표시됩니다. 파란색 글꼴의 입력값만 수정하면 모든 가치평가 결과가 자동으로 갱신됩니다. | E31: 모델 상태는 요약 및 검증 시트에 표시됩니다. 파란색 글꼴의 입력값만 수정하면 모든 가치평가 결과가 자동으로 갱신됩니다. | F31: 모델 상태는 요약 및 검증 시트에 표시됩니다. 파란색 글꼴의 입력값만 수정하면 모든 가치평가 결과가 자동으로 갱신됩니다. | G31: 모델 상태는 요약 및 검증 시트에 표시됩니다. 파란색 글꼴의 입력값만 수정하면 모든 가치평가 결과가 자동으로 갱신됩니다. | H31: 모델 상태는 요약 및 검증 시트에 표시됩니다. 파란색 글꼴의 입력값만 수정하면 모든 가치평가 결과가 자동으로 갱신됩니다.

Sheet 요약
B1: ㈜오리온 | FDD 조정 DCF 가치평가 요약 | C1: ㈜오리온 DCF 가치평가 요약 | D1: ㈜오리온 DCF 가치평가 요약 | E1: ㈜오리온 DCF 가치평가 요약 | F1: ㈜오리온 DCF 가치평가 요약 | G1: ㈜오리온 DCF 가치평가 요약 | H1: ㈜오리온 DCF 가치평가 요약 | I1: ㈜오리온 DCF 가치평가 요약 | J1: ㈜오리온 DCF 가치평가 요약
B2: ㈜오리온 DCF 가치평가 요약 | C2: ㈜오리온 DCF 가치평가 요약 | D2: ㈜오리온 DCF 가치평가 요약 | E2: ㈜오리온 DCF 가치평가 요약 | F2: ㈜오리온 DCF 가치평가 요약 | G2: ㈜오리온 DCF 가치평가 요약 | H2: ㈜오리온 DCF 가치평가 요약 | I2: ㈜오리온 DCF 가치평가 요약 | J2: ㈜오리온 DCF 가치평가 요약
B4: FDD 조정 가치평가 | G4: 영업실적 및 핵심 지표
B5: DCF 기업가치 | C5: =기업가치_지분가치!C5 -> 6530454.2 | D5: FDD 조정 FCFF의 현재가치 | G5: 2025년 공시 EBITDA | H5: ='FDD 조정'!E6 -> 722873.92
B6: 순차입금 조정(순현금은 +) | C6: =기업가치_지분가치!C10 -> 1186614.7 | D6: Cash-like - Debt-like | G6: 2025년 FDD 조정 EBITDA | H6: ='FDD 조정'!E13 -> 718602.22
B7: 비영업자산 | C7: ='FDD 조정'!E68 -> 1801499 | D7: 시장가치·공정가치·장부금액 | G7: QoE 조정액 | H7: ='FDD 조정'!E13-'FDD 조정'!E6 -> -4271.705
B8: 비지배지분 | C8: =-'FDD 조정'!E69 -> -103543.7 | D8: 연결 EV 귀속 조정 | G8: 2025년 영업이익률 | H8: =과거재무제표!F23 -> 0.16752218
B9: NWC 가격조정 | C9: ='FDD 조정'!E70 -> 0 | D9: 기본 0%. 거래 메커니즘 적용 시 변경 | G9: 2026~2030년 매출액 CAGR | H9: =(영업실적추정!J7/영업실적추정!F7)^(1/4)-1 -> 0.045445834
B10: FDD 조정 지분가치 | C10: =기업가치_지분가치!C27 -> 9415024.2 | D10: 기업가치 + FDD bridge | G10: 2030년 영업이익률 | H10: =영업실적추정!J18 -> 0.181
B11: 유통주식수(백만주) | C11: =기업가치_지분가치!C28 -> 39.528788 | D11: 발행주식수 - 자기주식수 | G11: 2026년 FCFF | H11: =DCF!C15 -> 269051.07
B12: 주당 FDD 조정 내재가치 | C12: =기업가치_지분가치!C29 -> 238181.45 | D12: 핵심 산출값 | G12: 2030년 FCFF | H12: =DCF!G15 -> 562920.61
B13: 2025년 12월 평균주가 | C13: =기업가치_지분가치!C30 -> 104330 | D13: 월평균 참고주가 | G13: EV / 2025년 FDD 조정 EBITDA | H13: =DCF!C29/'FDD 조정'!E13 -> 9.0877178
B14: 내재 상승여력 / (하락위험) | C14: =기업가치_지분가치!C31 -> 1.2829623 | D14: 내재가치 / 참고주가 - 1 | G14: 계속기업가치 / EV | H14: =DCF!C30 -> 0.74767596
B17: FDD 검토 결론
B18: 공개자료에서 식별되는 핵심 조정은 투자부동산 이중계상 제거와 IFRS 16 리스 처리 일관성 확보입니다. 투자부동산의 임대이익과 감가상각비를 영업가치에서 제외하고 공정가치를 별도 가산했습니다. 리스부채를 지분가치에서 차감하는 대신 사용권자산 추가액을 Capex에 포함했습니다. QoE의 기타 조정은 상세원장 없이 임의로 만들지 않았으며, 월별 NWC와 debt-like 상세를 확보할 때 입력할 수 있도록 분리했습니다.
B23: 영업가치 DCF는 지역별 매출액 추정, 명시적인 원가율, 정상화 현금법인세율, 핵심 운전자본 회전일수 및 공시된 진천공장 투자계획을 반영한 2026~2027년 Capex를 기초로 산정합니다. 오리온은 상당한 단기금융상품과 상장사 리가켐바이오 지분을 보유하는 반면 공시상 금융기관차입금은 사실상 없으므로 기업가치-지분가치 조정이 중요합니다. 따라서 본 모델은 당기순이익을 자본환원하지 않고 영업가치와 비영업자산을 구분합니다. | C23: 영업가치 DCF는 지역별 매출액 추정, 명시적인 원가율, 정상화 현금법인세율, 핵심 운전자본 회전일수 및 공시된 진천공장 투자계획을 반영한 2026~2027년 Capex를 기초로 산정합니다. 오리온은 상당한 단기금융상품과 상장사 리가켐바이오 지분을 보유하는 반면 공시상 금융기관차입금은 사실상 없으므로 기업가치-지분가치 조정이 중요합니다. 따라서 본 모델은 당기순이익을 자본환원하지 않고 영업가치와 비영업자산을 구분합니다. | D23: 영업가치 DCF는 지역별 매출액 추정, 명시적인 원가율, 정상화 현금법인세율, 핵심 운전자본 회전일수 및 공시된 진천공장 투자계획을 반영한 2026~2027년 Capex를 기초로 산정합니다. 오리온은 상당한 단기금융상품과 상장사 리가켐바이오 지분을 보유하는 반면 공시상 금융기관차입금은 사실상 없으므로 기업가치-지분가치 조정이 중요합니다. 따라서 본 모델은 당기순이익을 자본환원하지 않고 영업가치와 비영업자산을 구분합니다. | E23: 영업가치 DCF는 지역별 매출액 추정, 명시적인 원가율, 정상화 현금법인세율, 핵심 운전자본 회전일수 및 공시된 진천공장 투자계획을 반영한 2026~2027년 Capex를 기초로 산정합니다. 오리온은 상당한 단기금융상품과 상장사 리가켐바이오 지분을 보유하는 반면 공시상 금융기관차입금은 사실상 없으므로 기업가치-지분가치 조정이 중요합니다. 따라서 본 모델은 당기순이익을 자본환원하지 않고 영업가치와 비영업자산을 구분합니다. | F23: 영업가치 DCF는 지역별 매출액 추정, 명시적인 원가율, 정상화 현금법인세율, 핵심 운전자본 회전일수 및 공시된 진천공장 투자계획을 반영한 2026~2027년 Capex를 기초로 산정합니다. 오리온은 상당한 단기금융상품과 상장사 리가켐바이오 지분을 보유하는 반면 공시상 금융기관차입금은 사실상 없으므로 기업가치-지분가치 조정이 중요합니다. 따라서 본 모델은 당기순이익을 자본환원하지 않고 영업가치와 비영업자산을 구분합니다. | G23: 영업가치 DCF는 지역별 매출액 추정, 명시적인 원가율, 정상화 현금법인세율, 핵심 운전자본 회전일수 및 공시된 진천공장 투자계획을 반영한 2026~2027년 Capex를 기초로 산정합니다. 오리온은 상당한 단기금융상품과 상장사 리가켐바이오 지분을 보유하는 반면 공시상 금융기관차입금은 사실상 없으므로 기업가치-지분가치 조정이 중요합니다. 따라서 본 모델은 당기순이익을 자본환원하지 않고 영업가치와 비영업자산을 구분합니다. | H23: 영업가치 DCF는 지역별 매출액 추정, 명시적인 원가율, 정상화 현금법인세율, 핵심 운전자본 회전일수 및 공시된 진천공장 투자계획을 반영한 2026~2027년 Capex를 기초로 산정합니다. 오리온은 상당한 단기금융상품과 상장사 리가켐바이오 지분을 보유하는 반면 공시상 금융기관차입금은 사실상 없으므로 기업가치-지분가치 조정이 중요합니다. 따라서 본 모델은 당기순이익을 자본환원하지 않고 영업가치와 비영업자산을 구분합니다. | I23: 영업가치 DCF는 지역별 매출액 추정, 명시적인 원가율, 정상화 현금법인세율, 핵심 운전자본 회전일수 및 공시된 진천공장 투자계획을 반영한 2026~2027년 Capex를 기초로 산정합니다. 오리온은 상당한 단기금융상품과 상장사 리가켐바이오 지분을 보유하는 반면 공시상 금융기관차입금은 사실상 없으므로 기업가치-지분가치 조정이 중요합니다. 따라서 본 모델은 당기순이익을 자본환원하지 않고 영업가치와 비영업자산을 구분합니다. | J23: 영업가치 DCF는 지역별 매출액 추정, 명시적인 원가율, 정상화 현금법인세율, 핵심 운전자본 회전일수 및 공시된 진천공장 투자계획을 반영한 2026~2027년 Capex를 기초로 산정합니다. 오리온은 상당한 단기금융상품과 상장사 리가켐바이오 지분을 보유하는 반면 공시상 금융기관차입금은 사실상 없으므로 기업가치-지분가치 조정이 중요합니다. 따라서 본 모델은 당기순이익을 자본환원하지 않고 영업가치와 비영업자산을 구분합니다.
B25: 선택 민감도 범위 | C25: 선택 민감도 범위 | D25: 선택 민감도 범위 | E25: 선택 민감도 범위 | F25: 선택 민감도 범위 | G25: 선택 민감도 범위 | H25: 선택 민감도 범위 | I25: 선택 민감도 범위 | J25: 선택 민감도 범위
B26: =민감도분석!B5 -> 영구성장률 / WACC | C26: =민감도분석!C5 -> 0.085 | D26: =민감도분석!D5 -> 0.09 | E26: =민감도분석!E5 -> 0.095 | F26: =민감도분석!F5 -> 0.1 | G26: =민감도분석!G5 -> 0.105 | I26: 모델 상태 | J26: 모델 상태
B27: =민감도분석!B6 -> 0.01 | C27: =민감도분석!C6 -> 243416.68 | D27: =민감도분석!D6 -> 232099 | E27: =민감도분석!E6 -> 222121.85 | F27: =민감도분석!F6 -> 213261.65 | G27: =민감도분석!G6 -> 205341.87 | I27: 모델 상태 | J27: 모델 상태
B28: =민감도분석!B7 -> 0.015 | C28: =민감도분석!C7 -> 253203.14 | D28: =민감도분석!D7 -> 240506.1 | E28: =민감도분석!E7 -> 229405.32 | F28: =민감도분석!F7 -> 219618.93 | G28: =민감도분석!G7 -> 210927.71 | I28: 모델 상태 | J28: 모델 상태
B29: =민감도분석!B8 -> 0.02 | C29: =민감도분석!C8 -> 264495.2 | D29: =민감도분석!D8 -> 250114.22 | E29: =민감도분석!E8 -> 237659.92 | F29: =민감도분석!F8 -> 226770.87 | G29: =민감도분석!G8 -> 217170.7 | I29: =검증!C25 -> 정상
B30: =민감도분석!B9 -> 0.025 | C30: =민감도분석!C9 -> 277669.27 | D30: =민감도분석!D9 -> 261200.51 | E30: =민감도분석!E9 -> 247093.74 | F30: =민감도분석!F9 -> 234876.4 | G30: =민감도분석!G9 -> 224194.08
B31: =민감도분석!B10 -> 0.03 | C31: =민감도분석!C10 -> 293238.63 | D31: =민감도분석!D10 -> 274134.52 | E31: =민감도분석!E10 -> 257978.93 | F31: =민감도분석!F10 -> 244139.87 | G31: =민감도분석!G10 -> 232153.9

Sheet 가정
B1: 주요 가정 및 추정 동인 | C1: 주요 가정 및 추정 동인 | D1: 주요 가정 및 추정 동인 | E1: 주요 가정 및 추정 동인 | F1: 주요 가정 및 추정 동인 | G1: 주요 가정 및 추정 동인 | H1: 주요 가정 및 추정 동인 | I1: 주요 가정 및 추정 동인 | J1: 주요 가정 및 추정 동인 | K1: 주요 가정 및 추정 동인 | L1: 주요 가정 및 추정 동인 | M1: 주요 가정 및 추정 동인
B2: 주요 가정 및 추정 동인 | C2: 주요 가정 및 추정 동인 | D2: 주요 가정 및 추정 동인 | E2: 주요 가정 및 추정 동인 | F2: 주요 가정 및 추정 동인 | G2: 주요 가정 및 추정 동인 | H2: 주요 가정 및 추정 동인 | I2: 주요 가정 및 추정 동인 | J2: 주요 가정 및 추정 동인 | K2: 주요 가정 및 추정 동인 | L2: 주요 가정 및 추정 동인 | M2: 주요 가정 및 추정 동인
B4: 동인 | C4: 45291 | D4: 45657 | E4: 46022 | F4: 46387 | G4: 46752 | H4: 47118 | I4: 47483 | J4: 47848 | L4: 가정 근거 | M4: 입력 구분
B6: 지역별 매출액 성장률 | C6: 지역별 매출액 성장률 | D6: 지역별 매출액 성장률 | E6: 지역별 매출액 성장률 | F6: 지역별 매출액 성장률 | G6: 지역별 매출액 성장률 | H6: 지역별 매출액 성장률 | I6: 지역별 매출액 성장률 | J6: 지역별 매출액 성장률 | K6: 지역별 매출액 성장률 | L6: 지역별 매출액 성장률 | M6: 지역별 매출액 성장률
B7: 한국 성장률 | E7: =과거재무제표!F71/과거재무제표!E71-1 -> 0.03432495 | F7: 0.04 | G7: 0.035 | H7: 0.03 | I7: 0.03 | J7: 0.025 | L7: 성숙한 국내 시장을 고려하여 장기 물가상승률 수준으로 성장률 수렴 | M7: 수정 가능
B8: 중국 성장률 | E8: =과거재무제표!F72/과거재무제표!E72-1 -> 0.040464881 | F8: 0.045 | G8: 0.04 | H8: 0.035 | I8: 0.035 | J8: 0.03 | L8: 판매채널 확대 및 시장 성장률 정상화 | M8: 수정 가능
B9: 기타 국가 성장률 | E9: =과거재무제표!F73/과거재무제표!E73-1 -> 0.18040356 | F9: 0.11 | G9: 0.09 | H9: 0.08 | I9: 0.07 | J9: 0.06 | L9: 베트남·러시아·인도의 생산능력 및 유통망 확대 | M9: 수정 가능
B10: 연결 매출액 성장률 | D10: =과거재무제표!E7/과거재무제표!D7-1 -> 0.065919273 | E10: =과거재무제표!F7/과거재무제표!E7-1 -> 0.073479086 | F10: =매출액추정!F14 -> 0.061287804 | G10: =매출액추정!G14 -> 0.052815534 | H10: =매출액추정!H14 -> 0.046858646 | I10: =매출액추정!I14 -> 0.044227683 | J10: =매출액추정!J14 -> 0.037936092 | L10: 가중평균 성장률 계산값 | M10: 수식
B12: 영업·법인세·재투자 가정 | C12: 영업·법인세·재투자 가정 | D12: 영업·법인세·재투자 가정 | E12: 영업·법인세·재투자 가정 | F12: 영업·법인세·재투자 가정 | G12: 영업·법인세·재투자 가정 | H12: 영업·법인세·재투자 가정 | I12: 영업·법인세·재투자 가정 | J12: 영업·법인세·재투자 가정 | K12: 영업·법인세·재투자 가정 | L12: 영업·법인세·재투자 가정 | M12: 영업·법인세·재투자 가정
B13: 매출원가율 | C13: =-과거재무제표!D8/과거재무제표!D7 -> 0.61288723 | D13: =-과거재무제표!E8/과거재무제표!E7 -> 0.61467652 | E13: =-과거재무제표!F8/과거재무제표!F7 -> 0.63290407 | F13: 0.63 | G13: 0.628 | H13: 0.626 | I13: 0.625 | J13: 0.624 | L13: 2025년 원재료비 부담이 점진적으로 완화된다고 가정 | M13: 수정 가능
B14: 판매비율 | C14: =-과거재무제표!D10/과거재무제표!D7 -> 0.16564332 | D14: =-과거재무제표!E10/과거재무제표!E7 -> 0.15979751 | E14: =-과거재무제표!F10/과거재무제표!F7 -> 0.14653588 | F14: 0.146 | G14: 0.145 | H14: 0.144 | I14: 0.144 | J14: 0.143 | L14: 규모의 경제 및 판매채널 생산성 개선 | M14: 수정 가능
B15: 일반관리비율 | C15: =-과거재무제표!D11/과거재무제표!D7 -> 0.052399869 | D15: =-과거재무제표!E11/과거재무제표!E7 -> 0.050420141 | E15: =-과거재무제표!F11/과거재무제표!F7 -> 0.053037872 | F15: 0.053 | G15: 0.053 | H15: 0.052 | I15: 0.052 | J15: 0.052 | L15: 본사 공통비의 안정적 유지 | M15: 수정 가능
B16: 정상화 유효법인세율 | C16: =과거재무제표!D24 -> 0.25967558 | D16: =과거재무제표!E24 -> 0.22967782 | E16: =과거재무제표!F24 -> 0.28534285 | F16: 0.255 | G16: 0.255 | H16: 0.255 | I16: 0.255 | J16: 0.255 | L16: 세전이익 기준 공시 유효세율을 참고한 NOPAT 세율. 현금납부세율과 구분 | M16: 수정 가능
B17: 감가상각비 및 무형자산상각비율 | C17: =과거재무제표!D27/과거재무제표!D7 -> 0.053974123 | D17: =과거재무제표!E27/과거재무제표!E7 -> 0.051686179 | E17: =과거재무제표!F27/과거재무제표!F7 -> 0.04939797 | F17: 0.05 | G17: 0.052 | H17: 0.054 | I17: 0.053 | J17: 0.051 | L17: 생산능력 증설에 따라 감가상각비 증가 | M17: 수정 가능
B18: 유지보수 Capex 비율 | C18: =과거재무제표!D30/과거재무제표!D7 -> 0.057961502 | D18: =과거재무제표!E30/과거재무제표!E7 -> 0.039672833 | E18: =과거재무제표!F30/과거재무제표!F7 -> 0.04390627 | F18: 0.044 | G18: 0.045 | H18: 0.048 | I18: 0.05 | J18: 0.051 | L18: 영구기간에는 D&A 수준으로 수렴 | M18: 수정 가능
B19: 공시 성장 Capex(백만원) | F19: 180000 | G19: 170000 | H19: 0 | I19: 0 | J19: 0 | L19: 진천공장 투자계획: 2027년까지 총 4,600억원, 잔여 집행액 3,500억원을 모델에 반영 | M19: 수정 가능
B21: 운전자본 가정 | C21: 운전자본 가정 | D21: 운전자본 가정 | E21: 운전자본 가정 | F21: 운전자본 가정 | G21: 운전자본 가정 | H21: 운전자본 가정 | I21: 운전자본 가정 | J21: 운전자본 가정 | K21: 운전자본 가정 | L21: 운전자본 가정 | M21: 운전자본 가정
B22: DSO | C22: =NWC!C10 -> 23.941282 | D22: =NWC!D10 -> 20.848109 | E22: =NWC!E10 -> 19.934253 | F22: 20 | G22: 20 | H22: 19.5 | I22: 19.5 | J22: 19 | L22: 매출채권 회수기간을 2025년 수준으로 유지 | M22: 수정 가능
B23: 재고자산 회전일수 | C23: =NWC!C12 -> 53.112946 | D23: =NWC!D12 -> 60.558815 | E23: =NWC!E12 -> 55.623463 | F23: 56 | G23: 56 | H23: 55 | I23: 55 | J23: 54 | L23: 원재료 매입 이후 재고자산 수준 정상화 | M23: 수정 가능
B24: DPO | C24: =NWC!C16 -> 25.094715 | D24: =NWC!D16 -> 31.215776 | E24: =NWC!E16 -> 25.235552 | F24: 26 | G24: 26.5 | H24: 27 | I24: 27.5 | J24: 28 | L24: 매입 결제조건이 점진적으로 개선된다고 가정 | M24: 수정 가능
B25: 기타 영업유동자산 / 매출액 | C25: =NWC!C14 -> 0.0078742358 | D25: =NWC!D14 -> 0.0083181598 | E25: =NWC!E14 -> 0.0085779254 | F25: 0.009 | G25: 0.009 | H25: 0.009 | I25: 0.009 | J25: 0.009 | L25: 기타유동자산 비율을 안정적으로 유지 | M25: 수정 가능
B26: 기타 영업유동부채 / 매출액 | C26: =NWC!C18 -> 0.072246106 | D26: =NWC!D18 -> 0.097011938 | E26: =NWC!E18 -> 0.080922308 | F26: 0.080922296 | G26: 0.080922296 | H26: 0.080922296 | I26: 0.080922296 | J26: 0.080922296 | L26: 2025년 기타 영업유동부채에서 CAPEX 미지급금 13,687백만원을 debt-like로 재분류한 FDD 조정 비율을 2026~2030E에 적용 | M26: 수정 가능
B29: 가치평가 가정 | C29: 가치평가 가정 | D29: 가치평가 가정 | E29: 가치평가 가정 | F29: 가치평가 가정 | G29: 가치평가 가정 | H29: 가치평가 가정 | I29: 가치평가 가정 | J29: 가치평가 가정 | K29: 가치평가 가정 | L29: 가치평가 가정 | M29: 가치평가 가정
B30: 무위험수익률 | C30: 0.031 | L30: 원화 장기 무위험수익률 예시값이며 실제 업무 시 최신 자료로 갱신 | M30: 수정 가능
B31: 주식위험프리미엄 | C31: 0.06 | L31: 성숙시장 ERP 예시값 | M31: 수정 가능
B32: 레버드 베타 | C32: 0.9 | L32: 레버드 베타 예시값 | M32: 수정 가능
B33: 가중평균 국가위험프리미엄 | C33: 0.013 | L33: 중국·베트남·러시아·인도 사업노출을 반영한 가중 조정값 | M33: 수정 가능
B34: 세전 타인자본비용 | C34: 0.045 | L34: 공시상 금융기관차입금이 사실상 없으나 예시 차입이자율 적용 | M34: 수정 가능
B35: 목표 자기자본 비중 | C35: 0.95 | L35: 목표 자본구조이며 실제 차입금 비중은 사실상 0% | M35: 수정 가능
B36: 목표 타인자본 비중 | C36: 0.05 | L36: 목표 자본구조 | M36: 수정 가능
B37: 영구성장률 | C37: 0.02 | L37: 명시적 추정기간 성장률보다 낮은 장기 명목성장률 | M37: 수정 가능
B38: 종료시점 EV / EBITDA 교차검증 | C38: 8 | L38: 교차검증 전용이며 기준 DCF를 산정하지 않음 | M38: 수정 가능
B39: 필요 영업현금 / 매출액 | C39: 0.02 | L39: 영업활동에 필요한 최소 유동성 보유액 | M39: 수정 가능

Sheet 과거재무제표
B1: 과거 연결재무제표 | C1: 과거 연결재무제표 | D1: 과거 연결재무제표 | E1: 과거 연결재무제표 | F1: 과거 연결재무제표 | G1: 과거 연결재무제표 | H1: 과거 연결재무제표
B2: 과거 연결재무제표 | C2: 과거 연결재무제표 | D2: 과거 연결재무제표 | E2: 과거 연결재무제표 | F2: 과거 연결재무제표 | G2: 과거 연결재무제표 | H2: 과거 연결재무제표
B4: 항목 | C4: 출처 | D4: 45291 | E4: 45657 | F4: 46022 | G4: 단위 | H4: 비고
B6: 연결포괄손익계산서 | C6: 연결포괄손익계산서 | D6: 연결포괄손익계산서 | E6: 연결포괄손익계산서 | F6: 연결포괄손익계산서 | G6: 연결포괄손익계산서 | H6: 연결포괄손익계산서
B7: 매출액 | C7: S1 | D7: 2912358.1 | E7: 3104338.6 | F7: 3332442.5 | G7: 백만원 | H7: 공시금액
B8: 매출원가 | C8: S1 | D8: -1784947.1 | E8: -1908164 | F8: -2109116.4 | G8: 백만원 | H8: 공시금액; 비용은 음수로 표시
B9: 매출총이익 | C9: S1 | D9: 1127411 | E9: 1196174.5 | F9: 1223326.1 | G9: 백만원 | H9: 공시금액
B10: 판매비 | C10: S1 | D10: -482412.67 | E10: -496065.57 | F10: -488322.41 | G10: 백만원 | H10: 공시금액
B11: 일반관리비 | C11: S1 | D11: -152607.18 | E11: -156521.19 | F11: -176745.66 | G11: 백만원 | H11: 공시금액
B12: EBIT | C12: S1 | D12: 492391.15 | E12: 543587.78 | F12: 558258.03 | G12: 백만원 | H12: 공시 영업이익
B13: 기타수익 및 기타비용 순액 | C13: S1 | D13: -7133.9277 | E13: -28951.492 | F13: -5488.6408 | G13: 백만원 | H13: 공시금액
B14: 금융수익 및 금융비용 순액 | C14: S1 | D14: 34191.345 | E14: 182215.01 | F14: 21255.408 | G14: 백만원 | H14: 2024년 파생상품평가이익의 일시적 증가 포함
B15: 관계기업 및 공동기업 지분법손익 | C15: S1 | D15: 569.34024 | E15: -4635.0106 | F15: -27472.419 | G15: 백만원 | H15: 영업가치 DCF에서 제외하고 지분가치 조정에 반영
B16: 법인세비용차감전순이익 | C16: S1 | D16: 520017.91 | E16: 692216.28 | F16: 546552.37 | G16: 백만원 | H16: 공시금액
B17: 법인세비용 | C17: S1 | D17: -135035.95 | E17: -158986.73 | F17: -155954.81 | G17: 백만원 | H17: 공시금액; 비용은 음수로 표시
B18: 당기순이익 | C18: S1 | D18: 384981.96 | E18: 533229.55 | F18: 390597.56 | G18: 백만원 | H18: 공시금액
B19: EBITDA | C19: 계산값 | D19: =D12+D27 -> 649583.12 | E19: =E12+E27 -> 704039.18 | F19: =F12+F27 -> 722873.92 | G19: 백만원 | H19: EBIT + 공시 D&A
B21: 매출액 성장률 | C21: 계산값 | E21: =E7/D7-1 -> 0.065919273 | F21: =F7/E7-1 -> 0.073479086
B22: 매출총이익률 | C22: 계산값 | D22: =D9/D7 -> 0.38711277 | E22: =E9/E7 -> 0.38532348 | F22: =F9/F7 -> 0.36709593
B23: 영업이익률 | C23: 계산값 | D23: =D12/D7 -> 0.16906958 | E23: =E12/E7 -> 0.17510583 | F23: =F12/F7 -> 0.16752218
B24: 유효법인세율 | C24: 계산값 | D24: =-D17/D16 -> 0.25967558 | E24: =-E17/E16 -> 0.22967782 | F24: =-F17/F16 -> 0.28534285
B26: 현금흐름 및 DCF 입력값 | C26: 현금흐름 및 DCF 입력값 | D26: 현금흐름 및 DCF 입력값 | E26: 현금흐름 및 DCF 입력값 | F26: 현금흐름 및 DCF 입력값 | G26: 현금흐름 및 DCF 입력값 | H26: 현금흐름 및 DCF 입력값
B27: D&A(사용권자산·투자부동산 포함) | C27: S2 | D27: 157191.97 | E27: 160451.4 | F27: 164615.89 | G27: 백만원 | H27: 사업부문 공시 D&A
B28: 유형자산 취득 | C28: S2 | D28: 166473.27 | E28: 106937.4 | F28: 122555.59 | G28: 백만원 | H28: 현금유출액을 모델상 양수로 표시
B29: 무형자산 취득 | C29: S2 | D29: 2331.3767 | E29: 16220.509 | F29: 23759.528 | G29: 백만원 | H29: 현금유출액을 모델상 양수로 표시
B30: 총 자본적지출(Capex) | C30: 계산값 | D30: =SUM(D28:D29) -> 168804.65 | E30: =SUM(E28:E29) -> 123157.91 | F30: =SUM(F28:F29) -> 146315.12 | G30: 백만원 | H30: 유형자산 및 무형자산 취득액 합계
B31: 영업활동현금흐름 | C31: S2 | D31: 436961.97 | E31: 651588.44 | F31: 537328.13 | G31: 백만원 | H31: 공시금액
B32: 영업자산·부채의 증감 | C32: S2 | D32: -107809.93 | E32: 68739.25 | F32: -69986.532 | G32: 백만원 | H32: 공시 현금흐름 변동액; 핵심 NWC 추정 동인에는 미사용
B34: 연결재무상태표 및 가치조정 입력값 | C34: 연결재무상태표 및 가치조정 입력값 | D34: 연결재무상태표 및 가치조정 입력값 | E34: 연결재무상태표 및 가치조정 입력값 | F34: 연결재무상태표 및 가치조정 입력값 | G34: 연결재무상태표 및 가치조정 입력값 | H34: 연결재무상태표 및 가치조정 입력값
B35: 현금및현금성자산 | C35: S3 | D35: 365849.67 | E35: 451277.28 | F35: 311390.94 | G35: 백만원 | H35: 공시금액
B36: 단기금융상품 | C36: S3 | D36: 730485.11 | E36: 606419.82 | F36: 986075.62 | G36: 백만원 | H36: 공시금액; 비영업 유동성으로 분류
B37: 유동 당기손익-공정가치측정 금융자산 | C37: S3 | D37: 0 | E37: 5000 | F37: 5000 | G37: 백만원 | H37: 공시금액
B38: 기타유동금융자산 | C38: S3 | D38: 57846.174 | E38: 64195.223 | F38: 31192.702 | G38: 백만원 | H38: 영업성·비영업성이 혼재하여 가치조정에서 제외
B39: 매출채권 | C39: S3 | D39: 191029 | E39: 177313.94 | F39: 181999.33 | G39: 백만원 | H39: 핵심 영업 NWC
B40: 재고자산 | C40: S3 | D40: 259736.43 | E40: 316592.2 | F40: 321414.68 | G40: 백만원 | H40: 핵심 영업 NWC
B41: 기타유동자산 | C41: S3 | D41: 22932.594 | E41: 25822.384 | F41: 28585.443 | G41: 백만원 | H41: 핵심 영업 NWC
B42: 유형자산 | C42: S3 | D42: 1658386 | E42: 1701534.3 | F42: 1716028.6 | G42: 백만원 | H42: 공시금액
B43: 무형자산 | C43: S3 | D43: 29911.554 | E43: 44970.456 | F43: 64846.197 | G43: 백만원 | H43: 공시금액
B44: 영업권 | C44: S3 | D44: 23848.783 | E44: 25149.516 | F44: 25371.717 | G44: 백만원 | H44: 공시금액
B45: 투자부동산 - 장부금액 | C45: S3 | D45: 35381.317 | E45: 35014.589 | F45: 39900.885 | G45: 백만원 | H45: 공시금액
...

Sheet 매출액추정
B1: 지역별 매출액 추정 | C1: 지역별 매출액 추정 | D1: 지역별 매출액 추정 | E1: 지역별 매출액 추정 | F1: 지역별 매출액 추정 | G1: 지역별 매출액 추정 | H1: 지역별 매출액 추정 | I1: 지역별 매출액 추정 | J1: 지역별 매출액 추정
B2: 지역별 매출액 추정 | C2: 지역별 매출액 추정 | D2: 지역별 매출액 추정 | E2: 지역별 매출액 추정 | F2: 지역별 매출액 추정 | G2: 지역별 매출액 추정 | H2: 지역별 매출액 추정 | I2: 지역별 매출액 추정 | J2: 지역별 매출액 추정
B4: 항목 | C4: 45291 | D4: 45657 | E4: 46022 | F4: 46387 | G4: 46752 | H4: 47118 | I4: 47483 | J4: 47848
B6: 지역별 매출액 전망 | C6: 지역별 매출액 전망 | D6: 지역별 매출액 전망 | E6: 지역별 매출액 전망 | F6: 지역별 매출액 전망 | G6: 지역별 매출액 전망 | H6: 지역별 매출액 전망 | I6: 지역별 매출액 전망 | J6: 지역별 매출액 전망
B7: 한국 매출액 | D7: =과거재무제표!E71 -> 1060287.3 | E7: =과거재무제표!F71 -> 1096681.6 | F7: =E7*(1+가정!F7) -> 1140548.8 | G7: =F7*(1+가정!G7) -> 1180468.1 | H7: =G7*(1+가정!H7) -> 1215882.1 | I7: =H7*(1+가정!I7) -> 1252358.6 | J7: =I7*(1+가정!J7) -> 1283667.5
B8: 성장률 | E8: =E7/D7-1 -> 0.03432495 | F8: =가정!F7 -> 0.04 | G8: =가정!G7 -> 0.035 | H8: =가정!H7 -> 0.03 | I8: =가정!I7 -> 0.03 | J8: =가정!J7 -> 0.025
B9: 중국 매출액 | D9: =과거재무제표!E72 -> 1265157.6 | E9: =과거재무제표!F72 -> 1316352 | F9: =E9*(1+가정!F8) -> 1375587.9 | G9: =F9*(1+가정!G8) -> 1430611.4 | H9: =G9*(1+가정!H8) -> 1480682.8 | I9: =H9*(1+가정!I8) -> 1532506.7 | J9: =I9*(1+가정!J8) -> 1578481.9
B10: 성장률 | E10: =E9/D9-1 -> 0.040464881 | F10: =가정!F8 -> 0.045 | G10: =가정!G8 -> 0.04 | H10: =가정!H8 -> 0.035 | I10: =가정!I8 -> 0.035 | J10: =가정!J8 -> 0.03
B11: 기타 국가 매출액 | D11: =과거재무제표!E73 -> 778893.73 | E11: =과거재무제표!F73 -> 919408.93 | F11: =E11*(1+가정!F9) -> 1020543.9 | G11: =F11*(1+가정!G9) -> 1112392.9 | H11: =G11*(1+가정!H9) -> 1201384.3 | I11: =H11*(1+가정!I9) -> 1285481.2 | J11: =I11*(1+가정!J9) -> 1362610.1
B12: 성장률 | E12: =E11/D11-1 -> 0.18040356 | F12: =가정!F9 -> 0.11 | G12: =가정!G9 -> 0.09 | H12: =가정!H9 -> 0.08 | I12: =가정!I9 -> 0.07 | J12: =가정!J9 -> 0.06
B13: 연결 매출액 | C13: =과거재무제표!D7 -> 2912358.1 | D13: =과거재무제표!E7 -> 3104338.6 | E13: =과거재무제표!F7 -> 3332442.5 | F13: =SUM(F7,F9,F11) -> 3536680.6 | G13: =SUM(G7,G9,G11) -> 3723472.3 | H13: =SUM(H7,H9,H11) -> 3897949.2 | I13: =SUM(I7,I9,I11) -> 4070346.4 | J13: =SUM(J7,J9,J11) -> 4224759.5
B14: 성장률 | D14: =D13/C13-1 -> 0.065919273 | E14: =E13/D13-1 -> 0.073479086 | F14: =F13/E13-1 -> 0.061287804 | G14: =G13/F13-1 -> 0.052815534 | H14: =H13/G13-1 -> 0.046858646 | I14: =I13/H13-1 -> 0.044227683 | J14: =J13/I13-1 -> 0.037936092
B15: 공시 연결 매출액 일치 검증 | C15: =C13-과거재무제표!D7 -> 0 | D15: =D13-과거재무제표!E7 -> 0 | E15: =E13-과거재무제표!F7 -> 0
B17: 추정 논리: 한국과 중국의 성장률은 성숙시장 명목성장률로 수렴하며, 베트남·러시아·인도는 생산능력 및 유통망 확장 초기 단계이므로 기타 국가가 주요 성장동인으로 유지됩니다. 2025년 러시아 공시 성장률 47.3%는 기계적으로 연장하지 않았습니다. | C17: 추정 논리: 한국과 중국의 성장률은 성숙시장 명목성장률로 수렴하며, 베트남·러시아·인도는 생산능력 및 유통망 확장 초기 단계이므로 기타 국가가 주요 성장동인으로 유지됩니다. 2025년 러시아 공시 성장률 47.3%는 기계적으로 연장하지 않았습니다. | D17: 추정 논리: 한국과 중국의 성장률은 성숙시장 명목성장률로 수렴하며, 베트남·러시아·인도는 생산능력 및 유통망 확장 초기 단계이므로 기타 국가가 주요 성장동인으로 유지됩니다. 2025년 러시아 공시 성장률 47.3%는 기계적으로 연장하지 않았습니다. | E17: 추정 논리: 한국과 중국의 성장률은 성숙시장 명목성장률로 수렴하며, 베트남·러시아·인도는 생산능력 및 유통망 확장 초기 단계이므로 기타 국가가 주요 성장동인으로 유지됩니다. 2025년 러시아 공시 성장률 47.3%는 기계적으로 연장하지 않았습니다. | F17: 추정 논리: 한국과 중국의 성장률은 성숙시장 명목성장률로 수렴하며, 베트남·러시아·인도는 생산능력 및 유통망 확장 초기 단계이므로 기타 국가가 주요 성장동인으로 유지됩니다. 2025년 러시아 공시 성장률 47.3%는 기계적으로 연장하지 않았습니다. | G17: 추정 논리: 한국과 중국의 성장률은 성숙시장 명목성장률로 수렴하며, 베트남·러시아·인도는 생산능력 및 유통망 확장 초기 단계이므로 기타 국가가 주요 성장동인으로 유지됩니다. 2025년 러시아 공시 성장률 47.3%는 기계적으로 연장하지 않았습니다. | H17: 추정 논리: 한국과 중국의 성장률은 성숙시장 명목성장률로 수렴하며, 베트남·러시아·인도는 생산능력 및 유통망 확장 초기 단계이므로 기타 국가가 주요 성장동인으로 유지됩니다. 2025년 러시아 공시 성장률 47.3%는 기계적으로 연장하지 않았습니다. | I17: 추정 논리: 한국과 중국의 성장률은 성숙시장 명목성장률로 수렴하며, 베트남·러시아·인도는 생산능력 및 유통망 확장 초기 단계이므로 기타 국가가 주요 성장동인으로 유지됩니다. 2025년 러시아 공시 성장률 47.3%는 기계적으로 연장하지 않았습니다. | J17: 추정 논리: 한국과 중국의 성장률은 성숙시장 명목성장률로 수렴하며, 베트남·러시아·인도는 생산능력 및 유통망 확장 초기 단계이므로 기타 국가가 주요 성장동인으로 유지됩니다. 2025년 러시아 공시 성장률 47.3%는 기계적으로 연장하지 않았습니다.
B18: 추정 논리: 한국과 중국의 성장률은 성숙시장 명목성장률로 수렴하며, 베트남·러시아·인도는 생산능력 및 유통망 확장 초기 단계이므로 기타 국가가 주요 성장동인으로 유지됩니다. 2025년 러시아 공시 성장률 47.3%는 기계적으로 연장하지 않았습니다. | C18: 추정 논리: 한국과 중국의 성장률은 성숙시장 명목성장률로 수렴하며, 베트남·러시아·인도는 생산능력 및 유통망 확장 초기 단계이므로 기타 국가가 주요 성장동인으로 유지됩니다. 2025년 러시아 공시 성장률 47.3%는 기계적으로 연장하지 않았습니다. | D18: 추정 논리: 한국과 중국의 성장률은 성숙시장 명목성장률로 수렴하며, 베트남·러시아·인도는 생산능력 및 유통망 확장 초기 단계이므로 기타 국가가 주요 성장동인으로 유지됩니다. 2025년 러시아 공시 성장률 47.3%는 기계적으로 연장하지 않았습니다. | E18: 추정 논리: 한국과 중국의 성장률은 성숙시장 명목성장률로 수렴하며, 베트남·러시아·인도는 생산능력 및 유통망 확장 초기 단계이므로 기타 국가가 주요 성장동인으로 유지됩니다. 2025년 러시아 공시 성장률 47.3%는 기계적으로 연장하지 않았습니다. | F18: 추정 논리: 한국과 중국의 성장률은 성숙시장 명목성장률로 수렴하며, 베트남·러시아·인도는 생산능력 및 유통망 확장 초기 단계이므로 기타 국가가 주요 성장동인으로 유지됩니다. 2025년 러시아 공시 성장률 47.3%는 기계적으로 연장하지 않았습니다. | G18: 추정 논리: 한국과 중국의 성장률은 성숙시장 명목성장률로 수렴하며, 베트남·러시아·인도는 생산능력 및 유통망 확장 초기 단계이므로 기타 국가가 주요 성장동인으로 유지됩니다. 2025년 러시아 공시 성장률 47.3%는 기계적으로 연장하지 않았습니다. | H18: 추정 논리: 한국과 중국의 성장률은 성숙시장 명목성장률로 수렴하며, 베트남·러시아·인도는 생산능력 및 유통망 확장 초기 단계이므로 기타 국가가 주요 성장동인으로 유지됩니다. 2025년 러시아 공시 성장률 47.3%는 기계적으로 연장하지 않았습니다. | I18: 추정 논리: 한국과 중국의 성장률은 성숙시장 명목성장률로 수렴하며, 베트남·러시아·인도는 생산능력 및 유통망 확장 초기 단계이므로 기타 국가가 주요 성장동인으로 유지됩니다. 2025년 러시아 공시 성장률 47.3%는 기계적으로 연장하지 않았습니다. | J18: 추정 논리: 한국과 중국의 성장률은 성숙시장 명목성장률로 수렴하며, 베트남·러시아·인도는 생산능력 및 유통망 확장 초기 단계이므로 기타 국가가 주요 성장동인으로 유지됩니다. 2025년 러시아 공시 성장률 47.3%는 기계적으로 연장하지 않았습니다.
B19: 추정 논리: 한국과 중국의 성장률은 성숙시장 명목성장률로 수렴하며, 베트남·러시아·인도는 생산능력 및 유통망 확장 초기 단계이므로 기타 국가가 주요 성장동인으로 유지됩니다. 2025년 러시아 공시 성장률 47.3%는 기계적으로 연장하지 않았습니다. | C19: 추정 논리: 한국과 중국의 성장률은 성숙시장 명목성장률로 수렴하며, 베트남·러시아·인도는 생산능력 및 유통망 확장 초기 단계이므로 기타 국가가 주요 성장동인으로 유지됩니다. 2025년 러시아 공시 성장률 47.3%는 기계적으로 연장하지 않았습니다. | D19: 추정 논리: 한국과 중국의 성장률은 성숙시장 명목성장률로 수렴하며, 베트남·러시아·인도는 생산능력 및 유통망 확장 초기 단계이므로 기타 국가가 주요 성장동인으로 유지됩니다. 2025년 러시아 공시 성장률 47.3%는 기계적으로 연장하지 않았습니다. | E19: 추정 논리: 한국과 중국의 성장률은 성숙시장 명목성장률로 수렴하며, 베트남·러시아·인도는 생산능력 및 유통망 확장 초기 단계이므로 기타 국가가 주요 성장동인으로 유지됩니다. 2025년 러시아 공시 성장률 47.3%는 기계적으로 연장하지 않았습니다. | F19: 추정 논리: 한국과 중국의 성장률은 성숙시장 명목성장률로 수렴하며, 베트남·러시아·인도는 생산능력 및 유통망 확장 초기 단계이므로 기타 국가가 주요 성장동인으로 유지됩니다. 2025년 러시아 공시 성장률 47.3%는 기계적으로 연장하지 않았습니다. | G19: 추정 논리: 한국과 중국의 성장률은 성숙시장 명목성장률로 수렴하며, 베트남·러시아·인도는 생산능력 및 유통망 확장 초기 단계이므로 기타 국가가 주요 성장동인으로 유지됩니다. 2025년 러시아 공시 성장률 47.3%는 기계적으로 연장하지 않았습니다. | H19: 추정 논리: 한국과 중국의 성장률은 성숙시장 명목성장률로 수렴하며, 베트남·러시아·인도는 생산능력 및 유통망 확장 초기 단계이므로 기타 국가가 주요 성장동인으로 유지됩니다. 2025년 러시아 공시 성장률 47.3%는 기계적으로 연장하지 않았습니다. | I19: 추정 논리: 한국과 중국의 성장률은 성숙시장 명목성장률로 수렴하며, 베트남·러시아·인도는 생산능력 및 유통망 확장 초기 단계이므로 기타 국가가 주요 성장동인으로 유지됩니다. 2025년 러시아 공시 성장률 47.3%는 기계적으로 연장하지 않았습니다. | J19: 추정 논리: 한국과 중국의 성장률은 성숙시장 명목성장률로 수렴하며, 베트남·러시아·인도는 생산능력 및 유통망 확장 초기 단계이므로 기타 국가가 주요 성장동인으로 유지됩니다. 2025년 러시아 공시 성장률 47.3%는 기계적으로 연장하지 않았습니다.
B20: 추정 논리: 한국과 중국의 성장률은 성숙시장 명목성장률로 수렴하며, 베트남·러시아·인도는 생산능력 및 유통망 확장 초기 단계이므로 기타 국가가 주요 성장동인으로 유지됩니다. 2025년 러시아 공시 성장률 47.3%는 기계적으로 연장하지 않았습니다. | C20: 추정 논리: 한국과 중국의 성장률은 성숙시장 명목성장률로 수렴하며, 베트남·러시아·인도는 생산능력 및 유통망 확장 초기 단계이므로 기타 국가가 주요 성장동인으로 유지됩니다. 2025년 러시아 공시 성장률 47.3%는 기계적으로 연장하지 않았습니다. | D20: 추정 논리: 한국과 중국의 성장률은 성숙시장 명목성장률로 수렴하며, 베트남·러시아·인도는 생산능력 및 유통망 확장 초기 단계이므로 기타 국가가 주요 성장동인으로 유지됩니다. 2025년 러시아 공시 성장률 47.3%는 기계적으로 연장하지 않았습니다. | E20: 추정 논리: 한국과 중국의 성장률은 성숙시장 명목성장률로 수렴하며, 베트남·러시아·인도는 생산능력 및 유통망 확장 초기 단계이므로 기타 국가가 주요 성장동인으로 유지됩니다. 2025년 러시아 공시 성장률 47.3%는 기계적으로 연장하지 않았습니다. | F20: 추정 논리: 한국과 중국의 성장률은 성숙시장 명목성장률로 수렴하며, 베트남·러시아·인도는 생산능력 및 유통망 확장 초기 단계이므로 기타 국가가 주요 성장동인으로 유지됩니다. 2025년 러시아 공시 성장률 47.3%는 기계적으로 연장하지 않았습니다. | G20: 추정 논리: 한국과 중국의 성장률은 성숙시장 명목성장률로 수렴하며, 베트남·러시아·인도는 생산능력 및 유통망 확장 초기 단계이므로 기타 국가가 주요 성장동인으로 유지됩니다. 2025년 러시아 공시 성장률 47.3%는 기계적으로 연장하지 않았습니다. | H20: 추정 논리: 한국과 중국의 성장률은 성숙시장 명목성장률로 수렴하며, 베트남·러시아·인도는 생산능력 및 유통망 확장 초기 단계이므로 기타 국가가 주요 성장동인으로 유지됩니다. 2025년 러시아 공시 성장률 47.3%는 기계적으로 연장하지 않았습니다. | I20: 추정 논리: 한국과 중국의 성장률은 성숙시장 명목성장률로 수렴하며, 베트남·러시아·인도는 생산능력 및 유통망 확장 초기 단계이므로 기타 국가가 주요 성장동인으로 유지됩니다. 2025년 러시아 공시 성장률 47.3%는 기계적으로 연장하지 않았습니다. | J20: 추정 논리: 한국과 중국의 성장률은 성숙시장 명목성장률로 수렴하며, 베트남·러시아·인도는 생산능력 및 유통망 확장 초기 단계이므로 기타 국가가 주요 성장동인으로 유지됩니다. 2025년 러시아 공시 성장률 47.3%는 기계적으로 연장하지 않았습니다.

Sheet 영업실적추정
B1: 영업실적 추정 | C1: 영업실적 추정 | D1: 영업실적 추정 | E1: 영업실적 추정 | F1: 영업실적 추정 | G1: 영업실적 추정 | H1: 영업실적 추정 | I1: 영업실적 추정 | J1: 영업실적 추정
B2: 영업실적 추정 | C2: 영업실적 추정 | D2: 영업실적 추정 | E2: 영업실적 추정 | F2: 영업실적 추정 | G2: 영업실적 추정 | H2: 영업실적 추정 | I2: 영업실적 추정 | J2: 영업실적 추정
B4: 항목 | C4: 45291 | D4: 45657 | E4: 46022 | F4: 46387 | G4: 46752 | H4: 47118 | I4: 47483 | J4: 47848
B6: 손익계산서 추정 | C6: 손익계산서 추정 | D6: 손익계산서 추정 | E6: 손익계산서 추정 | F6: 손익계산서 추정 | G6: 손익계산서 추정 | H6: 손익계산서 추정 | I6: 손익계산서 추정 | J6: 손익계산서 추정
B7: 매출액 | C7: =과거재무제표!D7 -> 2912358.1 | D7: =과거재무제표!E7 -> 3104338.6 | E7: =과거재무제표!F7 -> 3332442.5 | F7: =매출액추정!F13 -> 3536680.6 | G7: =매출액추정!G13 -> 3723472.3 | H7: =매출액추정!H13 -> 3897949.2 | I7: =매출액추정!I13 -> 4070346.4 | J7: =매출액추정!J13 -> 4224759.5
B8: 성장률 | D8: =D7/C7-1 -> 0.065919273 | E8: =E7/D7-1 -> 0.073479086 | F8: =F7/E7-1 -> 0.061287804 | G8: =G7/F7-1 -> 0.052815534 | H8: =H7/G7-1 -> 0.046858646 | I8: =I7/H7-1 -> 0.044227683 | J8: =J7/I7-1 -> 0.037936092
B9: 매출원가 | C9: =과거재무제표!D8 -> -1784947.1 | D9: =과거재무제표!E8 -> -1908164 | E9: =과거재무제표!F8 -> -2109116.4 | F9: =-F7*가정!F13 -> -2228108.8 | G9: =-G7*가정!G13 -> -2338340.6 | H9: =-H7*가정!H13 -> -2440116.2 | I9: =-I7*가정!I13 -> -2543966.5 | J9: =-J7*가정!J13 -> -2636249.9
B10: 매출원가율 | C10: =-C9/C7 -> 0.61288723 | D10: =-D9/D7 -> 0.61467652 | E10: =-E9/E7 -> 0.63290407 | F10: =-F9/F7 -> 0.63 | G10: =-G9/G7 -> 0.628 | H10: =-H9/H7 -> 0.626 | I10: =-I9/I7 -> 0.625 | J10: =-J9/J7 -> 0.624
B11: 매출총이익 | C11: =과거재무제표!D9 -> 1127411 | D11: =과거재무제표!E9 -> 1196174.5 | E11: =과거재무제표!F9 -> 1223326.1 | F11: =SUM(F7,F9) -> 1308571.8 | G11: =SUM(G7,G9) -> 1385131.7 | H11: =SUM(H7,H9) -> 1457833 | I11: =SUM(I7,I9) -> 1526379.9 | J11: =SUM(J7,J9) -> 1588509.6
B12: 매출총이익률 | C12: =C11/C7 -> 0.38711277 | D12: =D11/D7 -> 0.38532348 | E12: =E11/E7 -> 0.36709593 | F12: =F11/F7 -> 0.37 | G12: =G11/G7 -> 0.372 | H12: =H11/H7 -> 0.374 | I12: =I11/I7 -> 0.375 | J12: =J11/J7 -> 0.376
B13: 판매비 | C13: =과거재무제표!D10 -> -482412.67 | D13: =과거재무제표!E10 -> -496065.57 | E13: =과거재무제표!F10 -> -488322.41 | F13: =-F7*가정!F14 -> -516355.37 | G13: =-G7*가정!G14 -> -539903.48 | H13: =-H7*가정!H14 -> -561304.68 | I13: =-I7*가정!I14 -> -586129.89 | J13: =-J7*가정!J14 -> -604140.6
B14: 판매비율 | C14: =-C13/C7 -> 0.16564332 | D14: =-D13/D7 -> 0.15979751 | E14: =-E13/E7 -> 0.14653588 | F14: =-F13/F7 -> 0.146 | G14: =-G13/G7 -> 0.145 | H14: =-H13/H7 -> 0.144 | I14: =-I13/I7 -> 0.144 | J14: =-J13/J7 -> 0.143
B15: 일반관리비 | C15: =과거재무제표!D11 -> -152607.18 | D15: =과거재무제표!E11 -> -156521.19 | E15: =과거재무제표!F11 -> -176745.66 | F15: =-F7*가정!F15 -> -187444.07 | G15: =-G7*가정!G15 -> -197344.03 | H15: =-H7*가정!H15 -> -202693.36 | I15: =-I7*가정!I15 -> -211658.01 | J15: =-J7*가정!J15 -> -219687.49
B16: 일반관리비율 | C16: =-C15/C7 -> 0.052399869 | D16: =-D15/D7 -> 0.050420141 | E16: =-E15/E7 -> 0.053037872 | F16: =-F15/F7 -> 0.053 | G16: =-G15/G7 -> 0.053 | H16: =-H15/H7 -> 0.052 | I16: =-I15/I7 -> 0.052 | J16: =-J15/J7 -> 0.052
B17: EBIT | C17: =과거재무제표!D12 -> 492391.15 | D17: =과거재무제표!E12 -> 543587.78 | E17: =과거재무제표!F12 -> 558258.03 | F17: =SUM(F11,F13,F15) -> 604772.39 | G17: =SUM(G11,G13,G15) -> 647884.18 | H17: =SUM(H11,H13,H15) -> 693834.95 | I17: =SUM(I11,I13,I15) -> 728592.01 | J17: =SUM(J11,J13,J15) -> 764681.46
B18: 영업이익률 | C18: =C17/C7 -> 0.16906958 | D18: =D17/D7 -> 0.17510583 | E18: =E17/E7 -> 0.16752218 | F18: =F17/F7 -> 0.171 | G18: =G17/G7 -> 0.174 | H18: =H17/H7 -> 0.178 | I18: =I17/I7 -> 0.179 | J18: =J17/J7 -> 0.181
B19: D&A | C19: =과거재무제표!D27 -> 157191.97 | D19: =과거재무제표!E27 -> 160451.4 | E19: =과거재무제표!F27 -> 164615.89 | F19: ='Capex_D&A'!F8 -> 176834.03 | G19: ='Capex_D&A'!G8 -> 193620.56 | H19: ='Capex_D&A'!H8 -> 210489.26 | I19: ='Capex_D&A'!I8 -> 215728.36 | J19: ='Capex_D&A'!J8 -> 215462.73
B20: EBITDA | C20: =C17+C19 -> 649583.12 | D20: =D17+D19 -> 704039.18 | E20: =E17+E19 -> 722873.92 | F20: =SUM(F17,F19) -> 781606.42 | G20: =SUM(G17,G19) -> 841504.74 | H20: =SUM(H17,H19) -> 904324.21 | I20: =SUM(I17,I19) -> 944320.37 | J20: =SUM(J17,J19) -> 980144.2
B21: EBITDA 이익률 | C21: =C20/C7 -> 0.2230437 | D21: =D20/D7 -> 0.22679201 | E21: =E20/E7 -> 0.21692015 | F21: =F20/F7 -> 0.221 | G21: =G20/G7 -> 0.226 | H21: =H20/H7 -> 0.232 | I21: =I20/I7 -> 0.232 | J21: =J20/J7 -> 0.232
B22: 정상화 유효법인세율 | C22: =과거재무제표!D24 -> 0.25967558 | D22: =과거재무제표!E24 -> 0.22967782 | E22: =과거재무제표!F24 -> 0.28534285 | F22: =가정!F16 -> 0.255 | G22: =가정!G16 -> 0.255 | H22: =가정!H16 -> 0.255 | I22: =가정!I16 -> 0.255 | J22: =가정!J16 -> 0.255
B24: EBIT은 영업이익률을 직접 입력하지 않고 매출원가율, 판매비율 및 일반관리비율을 명시적으로 적용하여 추정합니다. 이에 따라 이익률 개선의 경제적 동인이 드러나며 실사 과정에서 가정 검토가 용이합니다. | C24: EBIT은 영업이익률을 직접 입력하지 않고 매출원가율, 판매비율 및 일반관리비율을 명시적으로 적용하여 추정합니다. 이에 따라 이익률 개선의 경제적 동인이 드러나며 실사 과정에서 가정 검토가 용이합니다. | D24: EBIT은 영업이익률을 직접 입력하지 않고 매출원가율, 판매비율 및 일반관리비율을 명시적으로 적용하여 추정합니다. 이에 따라 이익률 개선의 경제적 동인이 드러나며 실사 과정에서 가정 검토가 용이합니다. | E24: EBIT은 영업이익률을 직접 입력하지 않고 매출원가율, 판매비율 및 일반관리비율을 명시적으로 적용하여 추정합니다. 이에 따라 이익률 개선의 경제적 동인이 드러나며 실사 과정에서 가정 검토가 용이합니다. | F24: EBIT은 영업이익률을 직접 입력하지 않고 매출원가율, 판매비율 및 일반관리비율을 명시적으로 적용하여 추정합니다. 이에 따라 이익률 개선의 경제적 동인이 드러나며 실사 과정에서 가정 검토가 용이합니다. | G24: EBIT은 영업이익률을 직접 입력하지 않고 매출원가율, 판매비율 및 일반관리비율을 명시적으로 적용하여 추정합니다. 이에 따라 이익률 개선의 경제적 동인이 드러나며 실사 과정에서 가정 검토가 용이합니다. | H24: EBIT은 영업이익률을 직접 입력하지 않고 매출원가율, 판매비율 및 일반관리비율을 명시적으로 적용하여 추정합니다. 이에 따라 이익률 개선의 경제적 동인이 드러나며 실사 과정에서 가정 검토가 용이합니다. | I24: EBIT은 영업이익률을 직접 입력하지 않고 매출원가율, 판매비율 및 일반관리비율을 명시적으로 적용하여 추정합니다. 이에 따라 이익률 개선의 경제적 동인이 드러나며 실사 과정에서 가정 검토가 용이합니다. | J24: EBIT은 영업이익률을 직접 입력하지 않고 매출원가율, 판매비율 및 일반관리비율을 명시적으로 적용하여 추정합니다. 이에 따라 이익률 개선의 경제적 동인이 드러나며 실사 과정에서 가정 검토가 용이합니다.
B25: EBIT은 영업이익률을 직접 입력하지 않고 매출원가율, 판매비율 및 일반관리비율을 명시적으로 적용하여 추정합니다. 이에 따라 이익률 개선의 경제적 동인이 드러나며 실사 과정에서 가정 검토가 용이합니다. | C25: EBIT은 영업이익률을 직접 입력하지 않고 매출원가율, 판매비율 및 일반관리비율을 명시적으로 적용하여 추정합니다. 이에 따라 이익률 개선의 경제적 동인이 드러나며 실사 과정에서 가정 검토가 용이합니다. | D25: EBIT은 영업이익률을 직접 입력하지 않고 매출원가율, 판매비율 및 일반관리비율을 명시적으로 적용하여 추정합니다. 이에 따라 이익률 개선의 경제적 동인이 드러나며 실사 과정에서 가정 검토가 용이합니다. | E25: EBIT은 영업이익률을 직접 입력하지 않고 매출원가율, 판매비율 및 일반관리비율을 명시적으로 적용하여 추정합니다. 이에 따라 이익률 개선의 경제적 동인이 드러나며 실사 과정에서 가정 검토가 용이합니다. | F25: EBIT은 영업이익률을 직접 입력하지 않고 매출원가율, 판매비율 및 일반관리비율을 명시적으로 적용하여 추정합니다. 이에 따라 이익률 개선의 경제적 동인이 드러나며 실사 과정에서 가정 검토가 용이합니다. | G25: EBIT은 영업이익률을 직접 입력하지 않고 매출원가율, 판매비율 및 일반관리비율을 명시적으로 적용하여 추정합니다. 이에 따라 이익률 개선의 경제적 동인이 드러나며 실사 과정에서 가정 검토가 용이합니다. | H25: EBIT은 영업이익률을 직접 입력하지 않고 매출원가율, 판매비율 및 일반관리비율을 명시적으로 적용하여 추정합니다. 이에 따라 이익률 개선의 경제적 동인이 드러나며 실사 과정에서 가정 검토가 용이합니다. | I25: EBIT은 영업이익률을 직접 입력하지 않고 매출원가율, 판매비율 및 일반관리비율을 명시적으로 적용하여 추정합니다. 이에 따라 이익률 개선의 경제적 동인이 드러나며 실사 과정에서 가정 검토가 용이합니다. | J25: EBIT은 영업이익률을 직접 입력하지 않고 매출원가율, 판매비율 및 일반관리비율을 명시적으로 적용하여 추정합니다. 이에 따라 이익률 개선의 경제적 동인이 드러나며 실사 과정에서 가정 검토가 용이합니다.
B26: EBIT은 영업이익률을 직접 입력하지 않고 매출원가율, 판매비율 및 일반관리비율을 명시적으로 적용하여 추정합니다. 이에 따라 이익률 개선의 경제적 동인이 드러나며 실사 과정에서 가정 검토가 용이합니다. | C26: EBIT은 영업이익률을 직접 입력하지 않고 매출원가율, 판매비율 및 일반관리비율을 명시적으로 적용하여 추정합니다. 이에 따라 이익률 개선의 경제적 동인이 드러나며 실사 과정에서 가정 검토가 용이합니다. | D26: EBIT은 영업이익률을 직접 입력하지 않고 매출원가율, 판매비율 및 일반관리비율을 명시적으로 적용하여 추정합니다. 이에 따라 이익률 개선의 경제적 동인이 드러나며 실사 과정에서 가정 검토가 용이합니다. | E26: EBIT은 영업이익률을 직접 입력하지 않고 매출원가율, 판매비율 및 일반관리비율을 명시적으로 적용하여 추정합니다. 이에 따라 이익률 개선의 경제적 동인이 드러나며 실사 과정에서 가정 검토가 용이합니다. | F26: EBIT은 영업이익률을 직접 입력하지 않고 매출원가율, 판매비율 및 일반관리비율을 명시적으로 적용하여 추정합니다. 이에 따라 이익률 개선의 경제적 동인이 드러나며 실사 과정에서 가정 검토가 용이합니다. | G26: EBIT은 영업이익률을 직접 입력하지 않고 매출원가율, 판매비율 및 일반관리비율을 명시적으로 적용하여 추정합니다. 이에 따라 이익률 개선의 경제적 동인이 드러나며 실사 과정에서 가정 검토가 용이합니다. | H26: EBIT은 영업이익률을 직접 입력하지 않고 매출원가율, 판매비율 및 일반관리비율을 명시적으로 적용하여 추정합니다. 이에 따라 이익률 개선의 경제적 동인이 드러나며 실사 과정에서 가정 검토가 용이합니다. | I26: EBIT은 영업이익률을 직접 입력하지 않고 매출원가율, 판매비율 및 일반관리비율을 명시적으로 적용하여 추정합니다. 이에 따라 이익률 개선의 경제적 동인이 드러나며 실사 과정에서 가정 검토가 용이합니다. | J26: EBIT은 영업이익률을 직접 입력하지 않고 매출원가율, 판매비율 및 일반관리비율을 명시적으로 적용하여 추정합니다. 이에 따라 이익률 개선의 경제적 동인이 드러나며 실사 과정에서 가정 검토가 용이합니다.
B27: EBIT은 영업이익률을 직접 입력하지 않고 매출원가율, 판매비율 및 일반관리비율을 명시적으로 적용하여 추정합니다. 이에 따라 이익률 개선의 경제적 동인이 드러나며 실사 과정에서 가정 검토가 용이합니다. | C27: EBIT은 영업이익률을 직접 입력하지 않고 매출원가율, 판매비율 및 일반관리비율을 명시적으로 적용하여 추정합니다. 이에 따라 이익률 개선의 경제적 동인이 드러나며 실사 과정에서 가정 검토가 용이합니다. | D27: EBIT은 영업이익률을 직접 입력하지 않고 매출원가율, 판매비율 및 일반관리비율을 명시적으로 적용하여 추정합니다. 이에 따라 이익률 개선의 경제적 동인이 드러나며 실사 과정에서 가정 검토가 용이합니다. | E27: EBIT은 영업이익률을 직접 입력하지 않고 매출원가율, 판매비율 및 일반관리비율을 명시적으로 적용하여 추정합니다. 이에 따라 이익률 개선의 경제적 동인이 드러나며 실사 과정에서 가정 검토가 용이합니다. | F27: EBIT은 영업이익률을 직접 입력하지 않고 매출원가율, 판매비율 및 일반관리비율을 명시적으로 적용하여 추정합니다. 이에 따라 이익률 개선의 경제적 동인이 드러나며 실사 과정에서 가정 검토가 용이합니다. | G27: EBIT은 영업이익률을 직접 입력하지 않고 매출원가율, 판매비율 및 일반관리비율을 명시적으로 적용하여 추정합니다. 이에 따라 이익률 개선의 경제적 동인이 드러나며 실사 과정에서 가정 검토가 용이합니다. | H27: EBIT은 영업이익률을 직접 입력하지 않고 매출원가율, 판매비율 및 일반관리비율을 명시적으로 적용하여 추정합니다. 이에 따라 이익률 개선의 경제적 동인이 드러나며 실사 과정에서 가정 검토가 용이합니다. | I27: EBIT은 영업이익률을 직접 입력하지 않고 매출원가율, 판매비율 및 일반관리비율을 명시적으로 적용하여 추정합니다. 이에 따라 이익률 개선의 경제적 동인이 드러나며 실사 과정에서 가정 검토가 용이합니다. | J27: EBIT은 영업이익률을 직접 입력하지 않고 매출원가율, 판매비율 및 일반관리비율을 명시적으로 적용하여 추정합니다. 이에 따라 이익률 개선의 경제적 동인이 드러나며 실사 과정에서 가정 검토가 용이합니다.

Sheet NWC
B1: 순운전자본 명세 | C1: 순운전자본 명세 | D1: 순운전자본 명세 | E1: 순운전자본 명세 | F1: 순운전자본 명세 | G1: 순운전자본 명세 | H1: 순운전자본 명세 | I1: 순운전자본 명세 | J1: 순운전자본 명세
B2: 순운전자본 명세 | C2: 순운전자본 명세 | D2: 순운전자본 명세 | E2: 순운전자본 명세 | F2: 순운전자본 명세 | G2: 순운전자본 명세 | H2: 순운전자본 명세 | I2: 순운전자본 명세 | J2: 순운전자본 명세
B4: 항목 | C4: 45291 | D4: 45657 | E4: 46022 | F4: 46387 | G4: 46752 | H4: 47118 | I4: 47483 | J4: 47848
B6: 핵심 영업운전자본 | C6: 핵심 영업운전자본 | D6: 핵심 영업운전자본 | E6: 핵심 영업운전자본 | F6: 핵심 영업운전자본 | G6: 핵심 영업운전자본 | H6: 핵심 영업운전자본 | I6: 핵심 영업운전자본 | J6: 핵심 영업운전자본
B7: 매출액 | C7: =영업실적추정!C7 -> 2912358.1 | D7: =영업실적추정!D7 -> 3104338.6 | E7: =영업실적추정!E7 -> 3332442.5 | F7: =영업실적추정!F7 -> 3536680.6 | G7: =영업실적추정!G7 -> 3723472.3 | H7: =영업실적추정!H7 -> 3897949.2 | I7: =영업실적추정!I7 -> 4070346.4 | J7: =영업실적추정!J7 -> 4224759.5
B8: 매출원가(양수 표시) | C8: =-영업실적추정!C9 -> 1784947.1 | D8: =-영업실적추정!D9 -> 1908164 | E8: =-영업실적추정!E9 -> 2109116.4 | F8: =-영업실적추정!F9 -> 2228108.8 | G8: =-영업실적추정!G9 -> 2338340.6 | H8: =-영업실적추정!H9 -> 2440116.2 | I8: =-영업실적추정!I9 -> 2543966.5 | J8: =-영업실적추정!J9 -> 2636249.9
B9: 매출채권 | C9: =과거재무제표!D39 -> 191029 | D9: =과거재무제표!E39 -> 177313.94 | E9: =과거재무제표!F39 -> 181999.33 | F9: =F7/365*가정!F22 -> 193790.72 | G9: =G7/365*가정!G22 -> 204025.88 | H9: =H7/365*가정!H22 -> 208246.6 | I9: =I7/365*가정!I22 -> 217456.86 | J9: =J7/365*가정!J22 -> 219918.99
B10: 매출채권 회수기간 | C10: =C9/C7*365 -> 23.941282 | D10: =D9/D7*365 -> 20.848109 | E10: =E9/E7*365 -> 19.934253 | F10: =가정!F22 -> 20 | G10: =가정!G22 -> 20 | H10: =가정!H22 -> 19.5 | I10: =가정!I22 -> 19.5 | J10: =가정!J22 -> 19
B11: 재고자산 | C11: =과거재무제표!D40 -> 259736.43 | D11: =과거재무제표!E40 -> 316592.2 | E11: =과거재무제표!F40 -> 321414.68 | F11: =F8/365*가정!F23 -> 341846.83 | G11: =G8/365*가정!G23 -> 358759.11 | H11: =H8/365*가정!H23 -> 367688.74 | I11: =I8/365*가정!I23 -> 383337.42 | J11: =J8/365*가정!J23 -> 390020.53
B12: 재고자산 회전일수 | C12: =C11/C8*365 -> 53.112946 | D12: =D11/D8*365 -> 60.558815 | E12: =E11/E8*365 -> 55.623463 | F12: =가정!F23 -> 56 | G12: =가정!G23 -> 56 | H12: =가정!H23 -> 55 | I12: =가정!I23 -> 55 | J12: =가정!J23 -> 54
B13: 기타 영업유동자산 | C13: =과거재무제표!D41 -> 22932.594 | D13: =과거재무제표!E41 -> 25822.384 | E13: =과거재무제표!F41 -> 28585.443 | F13: =F7*가정!F25 -> 31830.126 | G13: =G7*가정!G25 -> 33511.251 | H13: =H7*가정!H25 -> 35081.543 | I13: =I7*가정!I25 -> 36633.118 | J13: =J7*가정!J25 -> 38022.835
B14: 매출액 대비 비율 | C14: =C13/C7 -> 0.0078742358 | D14: =D13/D7 -> 0.0083181598 | E14: =E13/E7 -> 0.0085779254 | F14: =가정!F25 -> 0.009 | G14: =가정!G25 -> 0.009 | H14: =가정!H25 -> 0.009 | I14: =가정!I25 -> 0.009 | J14: =가정!J25 -> 0.009
B15: 매입채무 | C15: =과거재무제표!D56 -> 122719.83 | D15: =과거재무제표!E56 -> 163191.29 | E15: =과거재무제표!F56 -> 145821.15 | F15: =F8/365*가정!F24 -> 158714.6 | G15: =G8/365*가정!G24 -> 169769.93 | H15: =H8/365*가정!H24 -> 180501.74 | I15: =I8/365*가정!I24 -> 191668.71 | J15: =J8/365*가정!J24 -> 202232.87
B16: 매입채무 회수기간 | C16: =C15/C8*365 -> 25.094715 | D16: =D15/D8*365 -> 31.215776 | E16: =E15/E8*365 -> 25.235552 | F16: =가정!F24 -> 26 | G16: =가정!G24 -> 26.5 | H16: =가정!H24 -> 27 | I16: =가정!I24 -> 27.5 | J16: =가정!J24 -> 28
B17: 기타 영업유동부채 | C17: =SUM(과거재무제표!D57:D58) -> 210406.53 | D17: =SUM(과거재무제표!E57:E58) -> 301157.9 | E17: =SUM(과거재무제표!F57:F58)-'FDD 조정'!E29 -> 269668.94 | F17: =F7*가정!F26 -> 286196.32 | G17: =G7*가정!G26 -> 301311.93 | H17: =H7*가정!H26 -> 315431 | I17: =I7*가정!I26 -> 329381.78 | J17: =J7*가정!J26 -> 341877.24
B18: 매출액 대비 비율 | C18: =C17/C7 -> 0.072246106 | D18: =D17/D7 -> 0.097011938 | E18: =E17/E7 -> 0.080922308 | F18: =가정!F26 -> 0.080922296 | G18: =가정!G26 -> 0.080922296 | H18: =가정!H26 -> 0.080922296 | I18: =가정!I26 -> 0.080922296 | J18: =가정!J26 -> 0.080922296
B19: 순운전자본 | C19: =SUM(C9,C11,C13,-C15,-C17) -> 140571.66 | D19: =SUM(D9,D11,D13,-D15,-D17) -> 55379.333 | E19: =SUM(E9,E11,E13,-E15,-E17) -> 116509.37 | F19: =SUM(F9,F11,F13,-F15,-F17) -> 122556.76 | G19: =SUM(G9,G11,G13,-G15,-G17) -> 125214.37 | H19: =SUM(H9,H11,H13,-H15,-H17) -> 115084.14 | I19: =SUM(I9,I11,I13,-I15,-I17) -> 116376.91 | J19: =SUM(J9,J11,J13,-J15,-J17) -> 103852.25
B20: 매출액 대비 비율 | C20: =C19/C7 -> 0.048267302 | D20: =D19/D7 -> 0.017839334 | E20: =E19/E7 -> 0.034962153 | F20: =F19/F7 -> 0.034653046 | G20: =G19/G7 -> 0.033628389 | H20: =H19/H7 -> 0.029524279 | I20: =I19/I7 -> 0.028591402 | J20: =J19/J7 -> 0.024581813
B21: NWC 증감 | D21: =D19-C19 -> -85192.331 | E21: =E19-D19 -> 61130.034 | F21: =F19-E19 -> 6047.3894 | G21: =G19-F19 -> 2657.6166 | H21: =H19-G19 -> -10130.235 | I21: =I19-H19 -> 1292.7734 | J21: =J19-I19 -> -12524.664
B23: 핵심 NWC는 매출채권, 재고자산 및 기타 영업유동자산에서 매입채무, 기타유동부채 및 기타유동금융부채를 차감하여 산정합니다. 현금, 금융상품, 법인세, 금융기관차입금 및 리스부채는 제외합니다. 2025년 공개자료로 확인된 CAPEX 관련 미지급금 13,687백만원은 FDD 조정 시트에서 debt-like로 재분류하여 운영 NWC에서도 제외합니다. | C23: 핵심 NWC는 매출채권, 재고자산 및 기타 영업유동자산에서 매입채무, 기타유동부채 및 기타유동금융부채를 차감하여 산정합니다. 현금, 금융상품, 법인세, 금융기관차입금 및 리스부채는 제외합니다. 2025년 공개자료로 확인된 CAPEX 관련 미지급금 13,687백만원은 FDD 조정 시트에서 debt-like로 재분류하여 운영 NWC에서도 제외합니다. | D23: 핵심 NWC는 매출채권, 재고자산 및 기타 영업유동자산에서 매입채무, 기타유동부채 및 기타유동금융부채를 차감하여 산정합니다. 현금, 금융상품, 법인세, 금융기관차입금 및 리스부채는 제외합니다. 2025년 공개자료로 확인된 CAPEX 관련 미지급금 13,687백만원은 FDD 조정 시트에서 debt-like로 재분류하여 운영 NWC에서도 제외합니다. | E23: 핵심 NWC는 매출채권, 재고자산 및 기타 영업유동자산에서 매입채무, 기타유동부채 및 기타유동금융부채를 차감하여 산정합니다. 현금, 금융상품, 법인세, 금융기관차입금 및 리스부채는 제외합니다. 2025년 공개자료로 확인된 CAPEX 관련 미지급금 13,687백만원은 FDD 조정 시트에서 debt-like로 재분류하여 운영 NWC에서도 제외합니다. | F23: 핵심 NWC는 매출채권, 재고자산 및 기타 영업유동자산에서 매입채무, 기타유동부채 및 기타유동금융부채를 차감하여 산정합니다. 현금, 금융상품, 법인세, 금융기관차입금 및 리스부채는 제외합니다. 2025년 공개자료로 확인된 CAPEX 관련 미지급금 13,687백만원은 FDD 조정 시트에서 debt-like로 재분류하여 운영 NWC에서도 제외합니다. | G23: 핵심 NWC는 매출채권, 재고자산 및 기타 영업유동자산에서 매입채무, 기타유동부채 및 기타유동금융부채를 차감하여 산정합니다. 현금, 금융상품, 법인세, 금융기관차입금 및 리스부채는 제외합니다. 2025년 공개자료로 확인된 CAPEX 관련 미지급금 13,687백만원은 FDD 조정 시트에서 debt-like로 재분류하여 운영 NWC에서도 제외합니다. | H23: 핵심 NWC는 매출채권, 재고자산 및 기타 영업유동자산에서 매입채무, 기타유동부채 및 기타유동금융부채를 차감하여 산정합니다. 현금, 금융상품, 법인세, 금융기관차입금 및 리스부채는 제외합니다. 2025년 공개자료로 확인된 CAPEX 관련 미지급금 13,687백만원은 FDD 조정 시트에서 debt-like로 재분류하여 운영 NWC에서도 제외합니다. | I23: 핵심 NWC는 매출채권, 재고자산 및 기타 영업유동자산에서 매입채무, 기타유동부채 및 기타유동금융부채를 차감하여 산정합니다. 현금, 금융상품, 법인세, 금융기관차입금 및 리스부채는 제외합니다. 2025년 공개자료로 확인된 CAPEX 관련 미지급금 13,687백만원은 FDD 조정 시트에서 debt-like로 재분류하여 운영 NWC에서도 제외합니다. | J23: 핵심 NWC는 매출채권, 재고자산 및 기타 영업유동자산에서 매입채무, 기타유동부채 및 기타유동금융부채를 차감하여 산정합니다. 현금, 금융상품, 법인세, 금융기관차입금 및 리스부채는 제외합니다. 2025년 공개자료로 확인된 CAPEX 관련 미지급금 13,687백만원은 FDD 조정 시트에서 debt-like로 재분류하여 운영 NWC에서도 제외합니다.
B24: 핵심 NWC는 매출채권, 재고자산 및 기타 영업유동자산에서 매입채무, 기타유동부채 및 기타유동금융부채를 차감하여 산정합니다. 현금, 금융상품, 법인세, 금융기관차입금 및 리스부채는 제외합니다. | C24: 핵심 NWC는 매출채권, 재고자산 및 기타 영업유동자산에서 매입채무, 기타유동부채 및 기타유동금융부채를 차감하여 산정합니다. 현금, 금융상품, 법인세, 금융기관차입금 및 리스부채는 제외합니다. | D24: 핵심 NWC는 매출채권, 재고자산 및 기타 영업유동자산에서 매입채무, 기타유동부채 및 기타유동금융부채를 차감하여 산정합니다. 현금, 금융상품, 법인세, 금융기관차입금 및 리스부채는 제외합니다. | E24: 핵심 NWC는 매출채권, 재고자산 및 기타 영업유동자산에서 매입채무, 기타유동부채 및 기타유동금융부채를 차감하여 산정합니다. 현금, 금융상품, 법인세, 금융기관차입금 및 리스부채는 제외합니다. | F24: 핵심 NWC는 매출채권, 재고자산 및 기타 영업유동자산에서 매입채무, 기타유동부채 및 기타유동금융부채를 차감하여 산정합니다. 현금, 금융상품, 법인세, 금융기관차입금 및 리스부채는 제외합니다. | G24: 핵심 NWC는 매출채권, 재고자산 및 기타 영업유동자산에서 매입채무, 기타유동부채 및 기타유동금융부채를 차감하여 산정합니다. 현금, 금융상품, 법인세, 금융기관차입금 및 리스부채는 제외합니다. | H24: 핵심 NWC는 매출채권, 재고자산 및 기타 영업유동자산에서 매입채무, 기타유동부채 및 기타유동금융부채를 차감하여 산정합니다. 현금, 금융상품, 법인세, 금융기관차입금 및 리스부채는 제외합니다. | I24: 핵심 NWC는 매출채권, 재고자산 및 기타 영업유동자산에서 매입채무, 기타유동부채 및 기타유동금융부채를 차감하여 산정합니다. 현금, 금융상품, 법인세, 금융기관차입금 및 리스부채는 제외합니다. | J24: 핵심 NWC는 매출채권, 재고자산 및 기타 영업유동자산에서 매입채무, 기타유동부채 및 기타유동금융부채를 차감하여 산정합니다. 현금, 금융상품, 법인세, 금융기관차입금 및 리스부채는 제외합니다.
B25: 핵심 NWC는 매출채권, 재고자산 및 기타 영업유동자산에서 매입채무, 기타유동부채 및 기타유동금융부채를 차감하여 산정합니다. 현금, 금융상품, 법인세, 금융기관차입금 및 리스부채는 제외합니다. | C25: 핵심 NWC는 매출채권, 재고자산 및 기타 영업유동자산에서 매입채무, 기타유동부채 및 기타유동금융부채를 차감하여 산정합니다. 현금, 금융상품, 법인세, 금융기관차입금 및 리스부채는 제외합니다. | D25: 핵심 NWC는 매출채권, 재고자산 및 기타 영업유동자산에서 매입채무, 기타유동부채 및 기타유동금융부채를 차감하여 산정합니다. 현금, 금융상품, 법인세, 금융기관차입금 및 리스부채는 제외합니다. | E25: 핵심 NWC는 매출채권, 재고자산 및 기타 영업유동자산에서 매입채무, 기타유동부채 및 기타유동금융부채를 차감하여 산정합니다. 현금, 금융상품, 법인세, 금융기관차입금 및 리스부채는 제외합니다. | F25: 핵심 NWC는 매출채권, 재고자산 및 기타 영업유동자산에서 매입채무, 기타유동부채 및 기타유동금융부채를 차감하여 산정합니다. 현금, 금융상품, 법인세, 금융기관차입금 및 리스부채는 제외합니다. | G25: 핵심 NWC는 매출채권, 재고자산 및 기타 영업유동자산에서 매입채무, 기타유동부채 및 기타유동금융부채를 차감하여 산정합니다. 현금, 금융상품, 법인세, 금융기관차입금 및 리스부채는 제외합니다. | H25: 핵심 NWC는 매출채권, 재고자산 및 기타 영업유동자산에서 매입채무, 기타유동부채 및 기타유동금융부채를 차감하여 산정합니다. 현금, 금융상품, 법인세, 금융기관차입금 및 리스부채는 제외합니다. | I25: 핵심 NWC는 매출채권, 재고자산 및 기타 영업유동자산에서 매입채무, 기타유동부채 및 기타유동금융부채를 차감하여 산정합니다. 현금, 금융상품, 법인세, 금융기관차입금 및 리스부채는 제외합니다. | J25: 핵심 NWC는 매출채권, 재고자산 및 기타 영업유동자산에서 매입채무, 기타유동부채 및 기타유동금융부채를 차감하여 산정합니다. 현금, 금융상품, 법인세, 금융기관차입금 및 리스부채는 제외합니다.
B26: 핵심 NWC는 매출채권, 재고자산 및 기타 영업유동자산에서 매입채무, 기타유동부채 및 기타유동금융부채를 차감하여 산정합니다. 현금, 금융상품, 법인세, 금융기관차입금 및 리스부채는 제외합니다. | C26: 핵심 NWC는 매출채권, 재고자산 및 기타 영업유동자산에서 매입채무, 기타유동부채 및 기타유동금융부채를 차감하여 산정합니다. 현금, 금융상품, 법인세, 금융기관차입금 및 리스부채는 제외합니다. | D26: 핵심 NWC는 매출채권, 재고자산 및 기타 영업유동자산에서 매입채무, 기타유동부채 및 기타유동금융부채를 차감하여 산정합니다. 현금, 금융상품, 법인세, 금융기관차입금 및 리스부채는 제외합니다. | E26: 핵심 NWC는 매출채권, 재고자산 및 기타 영업유동자산에서 매입채무, 기타유동부채 및 기타유동금융부채를 차감하여 산정합니다. 현금, 금융상품, 법인세, 금융기관차입금 및 리스부채는 제외합니다. | F26: 핵심 NWC는 매출채권, 재고자산 및 기타 영업유동자산에서 매입채무, 기타유동부채 및 기타유동금융부채를 차감하여 산정합니다. 현금, 금융상품, 법인세, 금융기관차입금 및 리스부채는 제외합니다. | G26: 핵심 NWC는 매출채권, 재고자산 및 기타 영업유동자산에서 매입채무, 기타유동부채 및 기타유동금융부채를 차감하여 산정합니다. 현금, 금융상품, 법인세, 금융기관차입금 및 리스부채는 제외합니다. | H26: 핵심 NWC는 매출채권, 재고자산 및 기타 영업유동자산에서 매입채무, 기타유동부채 및 기타유동금융부채를 차감하여 산정합니다. 현금, 금융상품, 법인세, 금융기관차입금 및 리스부채는 제외합니다. | I26: 핵심 NWC는 매출채권, 재고자산 및 기타 영업유동자산에서 매입채무, 기타유동부채 및 기타유동금융부채를 차감하여 산정합니다. 현금, 금융상품, 법인세, 금융기관차입금 및 리스부채는 제외합니다. | J26: 핵심 NWC는 매출채권, 재고자산 및 기타 영업유동자산에서 매입채무, 기타유동부채 및 기타유동금융부채를 차감하여 산정합니다. 현금, 금융상품, 법인세, 금융기관차입금 및 리스부채는 제외합니다.

Sheet Capex_D&A
B1: Capex 및 감가상각비 명세 | C1: Capex 및 감가상각비 명세 | D1: Capex 및 감가상각비 명세 | E1: Capex 및 감가상각비 명세 | F1: Capex 및 감가상각비 명세 | G1: Capex 및 감가상각비 명세 | H1: Capex 및 감가상각비 명세 | I1: Capex 및 감가상각비 명세 | J1: Capex 및 감가상각비 명세
B2: Capex 및 감가상각비 명세 | C2: Capex 및 감가상각비 명세 | D2: Capex 및 감가상각비 명세 | E2: Capex 및 감가상각비 명세 | F2: Capex 및 감가상각비 명세 | G2: Capex 및 감가상각비 명세 | H2: Capex 및 감가상각비 명세 | I2: Capex 및 감가상각비 명세 | J2: Capex 및 감가상각비 명세
B4: 항목 | C4: 45291 | D4: 45657 | E4: 46022 | F4: 46387 | G4: 46752 | H4: 47118 | I4: 47483 | J4: 47848
B6: 재투자 명세 | C6: 재투자 명세 | D6: 재투자 명세 | E6: 재투자 명세 | F6: 재투자 명세 | G6: 재투자 명세 | H6: 재투자 명세 | I6: 재투자 명세 | J6: 재투자 명세
B7: 매출액 | C7: =영업실적추정!C7 -> 2912358.1 | D7: =영업실적추정!D7 -> 3104338.6 | E7: =영업실적추정!E7 -> 3332442.5 | F7: =영업실적추정!F7 -> 3536680.6 | G7: =영업실적추정!G7 -> 3723472.3 | H7: =영업실적추정!H7 -> 3897949.2 | I7: =영업실적추정!I7 -> 4070346.4 | J7: =영업실적추정!J7 -> 4224759.5
B8: D&A | C8: =과거재무제표!D27 -> 157191.97 | D8: =과거재무제표!E27 -> 160451.4 | E8: =과거재무제표!F27 -> 164615.89 | F8: =F7*가정!F17 -> 176834.03 | G8: =G7*가정!G17 -> 193620.56 | H8: =H7*가정!H17 -> 210489.26 | I8: =I7*가정!I17 -> 215728.36 | J8: =J7*가정!J17 -> 215462.73
B9: 감가상각비 및 무형자산상각비율 | C9: =C8/C7 -> 0.053974123 | D9: =D8/D7 -> 0.051686179 | E9: =E8/E7 -> 0.04939797 | F9: =가정!F17 -> 0.05 | G9: =가정!G17 -> 0.052 | H9: =가정!H17 -> 0.054 | I9: =가정!I17 -> 0.053 | J9: =가정!J17 -> 0.051
B10: 유형자산 취득 | C10: =과거재무제표!D28 -> 166473.27 | D10: =과거재무제표!E28 -> 106937.4 | E10: =과거재무제표!F28 -> 122555.59
B11: 무형자산 취득 | C11: =과거재무제표!D29 -> 2331.3767 | D11: =과거재무제표!E29 -> 16220.509 | E11: =과거재무제표!F29 -> 23759.528
B12: 공시 총 Capex | C12: =SUM(C10:C11) -> 168804.65 | D12: =SUM(D10:D11) -> 123157.91 | E12: =SUM(E10:E11) -> 146315.12
B13: 유지보수 Capex | F13: =F7*가정!F18 -> 155613.95 | G13: =G7*가정!G18 -> 167556.25 | H13: =H7*가정!H18 -> 187101.56 | I13: =I7*가정!I18 -> 203517.32 | J13: =J7*가정!J18 -> 215462.73
B14: 공시 성장 Capex | F14: =가정!F19 -> 180000 | G14: =가정!G19 -> 170000 | H14: =가정!H19 -> 0 | I14: =가정!I19 -> 0 | J14: =가정!J19 -> 0
B15: 총 Capex(현금 + Lease capex) | C15: =C12+'FDD 조정'!C17 -> 189745.22 | D15: =D12+'FDD 조정'!D17 -> 158994.57 | E15: =E12+'FDD 조정'!E17 -> 158898.12 | F15: =SUM(F13:F14)+'FDD 조정'!G17 -> 349053.33 | G15: =SUM(G13:G14)+'FDD 조정'!H17 -> 351705.45 | H15: =SUM(H13:H14)+'FDD 조정'!I17 -> 201913.77 | I15: =SUM(I13:I14)+'FDD 조정'!J17 -> 218984.64 | J15: =SUM(J13:J14)+'FDD 조정'!K17 -> 231516.82
B16: 총 Capex / 매출액 | C16: =C15/C7 -> 0.065151748 | D16: =D15/D7 -> 0.051216891 | E16: =E15/E7 -> 0.047682179 | F16: =F15/F7 -> 0.098695181 | G16: =G15/G7 -> 0.094456309 | H16: =H15/H7 -> 0.0518 | I16: =I15/I7 -> 0.0538 | J16: =J15/J7 -> 0.0548
B17: 순투자(Capex - D&A) | C17: =C15-C8 -> 32553.248 | D17: =D15-D8 -> -1456.8277 | E17: =E15-E8 -> -5717.7724 | F17: =F15-F8 -> 172219.3 | G17: =G15-G8 -> 158084.89 | H17: =H15-H8 -> -8575.4882 | I17: =I15-I8 -> 3256.2771 | J17: =J15-J8 -> 16054.086
B18: 누적 추정 성장 Capex | F18: =F14 -> 180000 | G18: =F18+G14 -> 350000 | H18: =G18+H14 -> 350000 | I18: =H18+I14 -> 350000 | J18: =I18+J14 -> 350000
B20: Public FDD 자료는 2025~2027년 총 8,300억원 생산투자 계획(한국 진천 4,600억원, 베트남 1,300억원, 러시아 2,400억원)을 제시합니다. 다만 2025 기집행분, maintenance/growth 구분 및 국가별 현금 지급시점이 공개자료만으로 분해되지 않아 현재 DCF에는 기존의 2026~2027 명시적 성장 Capex 3,500억원만 계량 반영하고, 추가 금액은 DD 확인사항으로 유지합니다. | C20: Public FDD 자료는 2025~2027년 총 8,300억원 생산투자 계획(한국 진천 4,600억원, 베트남 1,300억원, 러시아 2,400억원)을 제시합니다. 다만 2025 기집행분, maintenance/growth 구분 및 국가별 현금 지급시점이 공개자료만으로 분해되지 않아 현재 DCF에는 기존의 2026~2027 명시적 성장 Capex 3,500억원만 계량 반영하고, 추가 금액은 DD 확인사항으로 유지합니다. | D20: Public FDD 자료는 2025~2027년 총 8,300억원 생산투자 계획(한국 진천 4,600억원, 베트남 1,300억원, 러시아 2,400억원)을 제시합니다. 다만 2025 기집행분, maintenance/growth 구분 및 국가별 현금 지급시점이 공개자료만으로 분해되지 않아 현재 DCF에는 기존의 2026~2027 명시적 성장 Capex 3,500억원만 계량 반영하고, 추가 금액은 DD 확인사항으로 유지합니다. | E20: Public FDD 자료는 2025~2027년 총 8,300억원 생산투자 계획(한국 진천 4,600억원, 베트남 1,300억원, 러시아 2,400억원)을 제시합니다. 다만 2025 기집행분, maintenance/growth 구분 및 국가별 현금 지급시점이 공개자료만으로 분해되지 않아 현재 DCF에는 기존의 2026~2027 명시적 성장 Capex 3,500억원만 계량 반영하고, 추가 금액은 DD 확인사항으로 유지합니다. | F20: Public FDD 자료는 2025~2027년 총 8,300억원 생산투자 계획(한국 진천 4,600억원, 베트남 1,300억원, 러시아 2,400억원)을 제시합니다. 다만 2025 기집행분, maintenance/growth 구분 및 국가별 현금 지급시점이 공개자료만으로 분해되지 않아 현재 DCF에는 기존의 2026~2027 명시적 성장 Capex 3,500억원만 계량 반영하고, 추가 금액은 DD 확인사항으로 유지합니다. | G20: Public FDD 자료는 2025~2027년 총 8,300억원 생산투자 계획(한국 진천 4,600억원, 베트남 1,300억원, 러시아 2,400억원)을 제시합니다. 다만 2025 기집행분, maintenance/growth 구분 및 국가별 현금 지급시점이 공개자료만으로 분해되지 않아 현재 DCF에는 기존의 2026~2027 명시적 성장 Capex 3,500억원만 계량 반영하고, 추가 금액은 DD 확인사항으로 유지합니다. | H20: Public FDD 자료는 2025~2027년 총 8,300억원 생산투자 계획(한국 진천 4,600억원, 베트남 1,300억원, 러시아 2,400억원)을 제시합니다. 다만 2025 기집행분, maintenance/growth 구분 및 국가별 현금 지급시점이 공개자료만으로 분해되지 않아 현재 DCF에는 기존의 2026~2027 명시적 성장 Capex 3,500억원만 계량 반영하고, 추가 금액은 DD 확인사항으로 유지합니다. | I20: Public FDD 자료는 2025~2027년 총 8,300억원 생산투자 계획(한국 진천 4,600억원, 베트남 1,300억원, 러시아 2,400억원)을 제시합니다. 다만 2025 기집행분, maintenance/growth 구분 및 국가별 현금 지급시점이 공개자료만으로 분해되지 않아 현재 DCF에는 기존의 2026~2027 명시적 성장 Capex 3,500억원만 계량 반영하고, 추가 금액은 DD 확인사항으로 유지합니다. | J20: Public FDD 자료는 2025~2027년 총 8,300억원 생산투자 계획(한국 진천 4,600억원, 베트남 1,300억원, 러시아 2,400억원)을 제시합니다. 다만 2025 기집행분, maintenance/growth 구분 및 국가별 현금 지급시점이 공개자료만으로 분해되지 않아 현재 DCF에는 기존의 2026~2027 명시적 성장 Capex 3,500억원만 계량 반영하고, 추가 금액은 DD 확인사항으로 유지합니다.
B21: 사업보고서는 2025년 6월부터 2027년 12월까지 총 4,600억원 규모의 진천공장 투자계획을 공시합니다. 정확한 현금 집행일정은 공시되지 않았으므로 본 모델은 2026~2027년 잔여 프로젝트 Capex를 3,500억원으로 가정하고 나머지는 2025 회계연도까지 집행 또는 확정된 것으로 처리합니다. 이는 명시적인 실사 확인사항입니다. | C21: 사업보고서는 2025년 6월부터 2027년 12월까지 총 4,600억원 규모의 진천공장 투자계획을 공시합니다. 정확한 현금 집행일정은 공시되지 않았으므로 본 모델은 2026~2027년 잔여 프로젝트 Capex를 3,500억원으로 가정하고 나머지는 2025 회계연도까지 집행 또는 확정된 것으로 처리합니다. 이는 명시적인 실사 확인사항입니다. | D21: 사업보고서는 2025년 6월부터 2027년 12월까지 총 4,600억원 규모의 진천공장 투자계획을 공시합니다. 정확한 현금 집행일정은 공시되지 않았으므로 본 모델은 2026~2027년 잔여 프로젝트 Capex를 3,500억원으로 가정하고 나머지는 2025 회계연도까지 집행 또는 확정된 것으로 처리합니다. 이는 명시적인 실사 확인사항입니다. | E21: 사업보고서는 2025년 6월부터 2027년 12월까지 총 4,600억원 규모의 진천공장 투자계획을 공시합니다. 정확한 현금 집행일정은 공시되지 않았으므로 본 모델은 2026~2027년 잔여 프로젝트 Capex를 3,500억원으로 가정하고 나머지는 2025 회계연도까지 집행 또는 확정된 것으로 처리합니다. 이는 명시적인 실사 확인사항입니다. | F21: 사업보고서는 2025년 6월부터 2027년 12월까지 총 4,600억원 규모의 진천공장 투자계획을 공시합니다. 정확한 현금 집행일정은 공시되지 않았으므로 본 모델은 2026~2027년 잔여 프로젝트 Capex를 3,500억원으로 가정하고 나머지는 2025 회계연도까지 집행 또는 확정된 것으로 처리합니다. 이는 명시적인 실사 확인사항입니다. | G21: 사업보고서는 2025년 6월부터 2027년 12월까지 총 4,600억원 규모의 진천공장 투자계획을 공시합니다. 정확한 현금 집행일정은 공시되지 않았으므로 본 모델은 2026~2027년 잔여 프로젝트 Capex를 3,500억원으로 가정하고 나머지는 2025 회계연도까지 집행 또는 확정된 것으로 처리합니다. 이는 명시적인 실사 확인사항입니다. | H21: 사업보고서는 2025년 6월부터 2027년 12월까지 총 4,600억원 규모의 진천공장 투자계획을 공시합니다. 정확한 현금 집행일정은 공시되지 않았으므로 본 모델은 2026~2027년 잔여 프로젝트 Capex를 3,500억원으로 가정하고 나머지는 2025 회계연도까지 집행 또는 확정된 것으로 처리합니다. 이는 명시적인 실사 확인사항입니다. | I21: 사업보고서는 2025년 6월부터 2027년 12월까지 총 4,600억원 규모의 진천공장 투자계획을 공시합니다. 정확한 현금 집행일정은 공시되지 않았으므로 본 모델은 2026~2027년 잔여 프로젝트 Capex를 3,500억원으로 가정하고 나머지는 2025 회계연도까지 집행 또는 확정된 것으로 처리합니다. 이는 명시적인 실사 확인사항입니다. | J21: 사업보고서는 2025년 6월부터 2027년 12월까지 총 4,600억원 규모의 진천공장 투자계획을 공시합니다. 정확한 현금 집행일정은 공시되지 않았으므로 본 모델은 2026~2027년 잔여 프로젝트 Capex를 3,500억원으로 가정하고 나머지는 2025 회계연도까지 집행 또는 확정된 것으로 처리합니다. 이는 명시적인 실사 확인사항입니다.
B22: 사업보고서는 2025년 6월부터 2027년 12월까지 총 4,600억원 규모의 진천공장 투자계획을 공시합니다. 정확한 현금 집행일정은 공시되지 않았으므로 본 모델은 2026~2027년 잔여 프로젝트 Capex를 3,500억원으로 가정하고 나머지는 2025 회계연도까지 집행 또는 확정된 것으로 처리합니다. 이는 명시적인 실사 확인사항입니다. | C22: 사업보고서는 2025년 6월부터 2027년 12월까지 총 4,600억원 규모의 진천공장 투자계획을 공시합니다. 정확한 현금 집행일정은 공시되지 않았으므로 본 모델은 2026~2027년 잔여 프로젝트 Capex를 3,500억원으로 가정하고 나머지는 2025 회계연도까지 집행 또는 확정된 것으로 처리합니다. 이는 명시적인 실사 확인사항입니다. | D22: 사업보고서는 2025년 6월부터 2027년 12월까지 총 4,600억원 규모의 진천공장 투자계획을 공시합니다. 정확한 현금 집행일정은 공시되지 않았으므로 본 모델은 2026~2027년 잔여 프로젝트 Capex를 3,500억원으로 가정하고 나머지는 2025 회계연도까지 집행 또는 확정된 것으로 처리합니다. 이는 명시적인 실사 확인사항입니다. | E22: 사업보고서는 2025년 6월부터 2027년 12월까지 총 4,600억원 규모의 진천공장 투자계획을 공시합니다. 정확한 현금 집행일정은 공시되지 않았으므로 본 모델은 2026~2027년 잔여 프로젝트 Capex를 3,500억원으로 가정하고 나머지는 2025 회계연도까지 집행 또는 확정된 것으로 처리합니다. 이는 명시적인 실사 확인사항입니다. | F22: 사업보고서는 2025년 6월부터 2027년 12월까지 총 4,600억원 규모의 진천공장 투자계획을 공시합니다. 정확한 현금 집행일정은 공시되지 않았으므로 본 모델은 2026~2027년 잔여 프로젝트 Capex를 3,500억원으로 가정하고 나머지는 2025 회계연도까지 집행 또는 확정된 것으로 처리합니다. 이는 명시적인 실사 확인사항입니다. | G22: 사업보고서는 2025년 6월부터 2027년 12월까지 총 4,600억원 규모의 진천공장 투자계획을 공시합니다. 정확한 현금 집행일정은 공시되지 않았으므로 본 모델은 2026~2027년 잔여 프로젝트 Capex를 3,500억원으로 가정하고 나머지는 2025 회계연도까지 집행 또는 확정된 것으로 처리합니다. 이는 명시적인 실사 확인사항입니다. | H22: 사업보고서는 2025년 6월부터 2027년 12월까지 총 4,600억원 규모의 진천공장 투자계획을 공시합니다. 정확한 현금 집행일정은 공시되지 않았으므로 본 모델은 2026~2027년 잔여 프로젝트 Capex를 3,500억원으로 가정하고 나머지는 2025 회계연도까지 집행 또는 확정된 것으로 처리합니다. 이는 명시적인 실사 확인사항입니다. | I22: 사업보고서는 2025년 6월부터 2027년 12월까지 총 4,600억원 규모의 진천공장 투자계획을 공시합니다. 정확한 현금 집행일정은 공시되지 않았으므로 본 모델은 2026~2027년 잔여 프로젝트 Capex를 3,500억원으로 가정하고 나머지는 2025 회계연도까지 집행 또는 확정된 것으로 처리합니다. 이는 명시적인 실사 확인사항입니다. | J22: 사업보고서는 2025년 6월부터 2027년 12월까지 총 4,600억원 규모의 진천공장 투자계획을 공시합니다. 정확한 현금 집행일정은 공시되지 않았으므로 본 모델은 2026~2027년 잔여 프로젝트 Capex를 3,500억원으로 가정하고 나머지는 2025 회계연도까지 집행 또는 확정된 것으로 처리합니다. 이는 명시적인 실사 확인사항입니다.
B23: 사업보고서는 2025년 6월부터 2027년 12월까지 총 4,600억원 규모의 진천공장 투자계획을 공시합니다. 정확한 현금 집행일정은 공시되지 않았으므로 본 모델은 2026~2027년 잔여 프로젝트 Capex를 3,500억원으로 가정하고 나머지는 2025 회계연도까지 집행 또는 확정된 것으로 처리합니다. 이는 명시적인 실사 확인사항입니다. | C23: 사업보고서는 2025년 6월부터 2027년 12월까지 총 4,600억원 규모의 진천공장 투자계획을 공시합니다. 정확한 현금 집행일정은 공시되지 않았으므로 본 모델은 2026~2027년 잔여 프로젝트 Capex를 3,500억원으로 가정하고 나머지는 2025 회계연도까지 집행 또는 확정된 것으로 처리합니다. 이는 명시적인 실사 확인사항입니다. | D23: 사업보고서는 2025년 6월부터 2027년 12월까지 총 4,600억원 규모의 진천공장 투자계획을 공시합니다. 정확한 현금 집행일정은 공시되지 않았으므로 본 모델은 2026~2027년 잔여 프로젝트 Capex를 3,500억원으로 가정하고 나머지는 2025 회계연도까지 집행 또는 확정된 것으로 처리합니다. 이는 명시적인 실사 확인사항입니다. | E23: 사업보고서는 2025년 6월부터 2027년 12월까지 총 4,600억원 규모의 진천공장 투자계획을 공시합니다. 정확한 현금 집행일정은 공시되지 않았으므로 본 모델은 2026~2027년 잔여 프로젝트 Capex를 3,500억원으로 가정하고 나머지는 2025 회계연도까지 집행 또는 확정된 것으로 처리합니다. 이는 명시적인 실사 확인사항입니다. | F23: 사업보고서는 2025년 6월부터 2027년 12월까지 총 4,600억원 규모의 진천공장 투자계획을 공시합니다. 정확한 현금 집행일정은 공시되지 않았으므로 본 모델은 2026~2027년 잔여 프로젝트 Capex를 3,500억원으로 가정하고 나머지는 2025 회계연도까지 집행 또는 확정된 것으로 처리합니다. 이는 명시적인 실사 확인사항입니다. | G23: 사업보고서는 2025년 6월부터 2027년 12월까지 총 4,600억원 규모의 진천공장 투자계획을 공시합니다. 정확한 현금 집행일정은 공시되지 않았으므로 본 모델은 2026~2027년 잔여 프로젝트 Capex를 3,500억원으로 가정하고 나머지는 2025 회계연도까지 집행 또는 확정된 것으로 처리합니다. 이는 명시적인 실사 확인사항입니다. | H23: 사업보고서는 2025년 6월부터 2027년 12월까지 총 4,600억원 규모의 진천공장 투자계획을 공시합니다. 정확한 현금 집행일정은 공시되지 않았으므로 본 모델은 2026~2027년 잔여 프로젝트 Capex를 3,500억원으로 가정하고 나머지는 2025 회계연도까지 집행 또는 확정된 것으로 처리합니다. 이는 명시적인 실사 확인사항입니다. | I23: 사업보고서는 2025년 6월부터 2027년 12월까지 총 4,600억원 규모의 진천공장 투자계획을 공시합니다. 정확한 현금 집행일정은 공시되지 않았으므로 본 모델은 2026~2027년 잔여 프로젝트 Capex를 3,500억원으로 가정하고 나머지는 2025 회계연도까지 집행 또는 확정된 것으로 처리합니다. 이는 명시적인 실사 확인사항입니다. | J23: 사업보고서는 2025년 6월부터 2027년 12월까지 총 4,600억원 규모의 진천공장 투자계획을 공시합니다. 정확한 현금 집행일정은 공시되지 않았으므로 본 모델은 2026~2027년 잔여 프로젝트 Capex를 3,500억원으로 가정하고 나머지는 2025 회계연도까지 집행 또는 확정된 것으로 처리합니다. 이는 명시적인 실사 확인사항입니다.
B24: 사업보고서는 2025년 6월부터 2027년 12월까지 총 4,600억원 규모의 진천공장 투자계획을 공시합니다. 정확한 현금 집행일정은 공시되지 않았으므로 본 모델은 2026~2027년 잔여 프로젝트 Capex를 3,500억원으로 가정하고 나머지는 2025 회계연도까지 집행 또는 확정된 것으로 처리합니다. 이는 명시적인 실사 확인사항입니다. | C24: 사업보고서는 2025년 6월부터 2027년 12월까지 총 4,600억원 규모의 진천공장 투자계획을 공시합니다. 정확한 현금 집행일정은 공시되지 않았으므로 본 모델은 2026~2027년 잔여 프로젝트 Capex를 3,500억원으로 가정하고 나머지는 2025 회계연도까지 집행 또는 확정된 것으로 처리합니다. 이는 명시적인 실사 확인사항입니다. | D24: 사업보고서는 2025년 6월부터 2027년 12월까지 총 4,600억원 규모의 진천공장 투자계획을 공시합니다. 정확한 현금 집행일정은 공시되지 않았으므로 본 모델은 2026~2027년 잔여 프로젝트 Capex를 3,500억원으로 가정하고 나머지는 2025 회계연도까지 집행 또는 확정된 것으로 처리합니다. 이는 명시적인 실사 확인사항입니다. | E24: 사업보고서는 2025년 6월부터 2027년 12월까지 총 4,600억원 규모의 진천공장 투자계획을 공시합니다. 정확한 현금 집행일정은 공시되지 않았으므로 본 모델은 2026~2027년 잔여 프로젝트 Capex를 3,500억원으로 가정하고 나머지는 2025 회계연도까지 집행 또는 확정된 것으로 처리합니다. 이는 명시적인 실사 확인사항입니다. | F24: 사업보고서는 2025년 6월부터 2027년 12월까지 총 4,600억원 규모의 진천공장 투자계획을 공시합니다. 정확한 현금 집행일정은 공시되지 않았으므로 본 모델은 2026~2027년 잔여 프로젝트 Capex를 3,500억원으로 가정하고 나머지는 2025 회계연도까지 집행 또는 확정된 것으로 처리합니다. 이는 명시적인 실사 확인사항입니다. | G24: 사업보고서는 2025년 6월부터 2027년 12월까지 총 4,600억원 규모의 진천공장 투자계획을 공시합니다. 정확한 현금 집행일정은 공시되지 않았으므로 본 모델은 2026~2027년 잔여 프로젝트 Capex를 3,500억원으로 가정하고 나머지는 2025 회계연도까지 집행 또는 확정된 것으로 처리합니다. 이는 명시적인 실사 확인사항입니다. | H24: 사업보고서는 2025년 6월부터 2027년 12월까지 총 4,600억원 규모의 진천공장 투자계획을 공시합니다. 정확한 현금 집행일정은 공시되지 않았으므로 본 모델은 2026~2027년 잔여 프로젝트 Capex를 3,500억원으로 가정하고 나머지는 2025 회계연도까지 집행 또는 확정된 것으로 처리합니다. 이는 명시적인 실사 확인사항입니다. | I24: 사업보고서는 2025년 6월부터 2027년 12월까지 총 4,600억원 규모의 진천공장 투자계획을 공시합니다. 정확한 현금 집행일정은 공시되지 않았으므로 본 모델은 2026~2027년 잔여 프로젝트 Capex를 3,500억원으로 가정하고 나머지는 2025 회계연도까지 집행 또는 확정된 것으로 처리합니다. 이는 명시적인 실사 확인사항입니다. | J24: 사업보고서는 2025년 6월부터 2027년 12월까지 총 4,600억원 규모의 진천공장 투자계획을 공시합니다. 정확한 현금 집행일정은 공시되지 않았으므로 본 모델은 2026~2027년 잔여 프로젝트 Capex를 3,500억원으로 가정하고 나머지는 2025 회계연도까지 집행 또는 확정된 것으로 처리합니다. 이는 명시적인 실사 확인사항입니다.

Sheet WACC
B1: 가중평균자본비용(WACC) | C1: 가중평균자본비용(WACC) | D1: 가중평균자본비용(WACC) | E1: 가중평균자본비용(WACC) | F1: 가중평균자본비용(WACC) | G1: 가중평균자본비용(WACC) | H1: 가중평균자본비용(WACC)
B2: 가중평균자본비용(WACC) | C2: 가중평균자본비용(WACC) | D2: 가중평균자본비용(WACC) | E2: 가중평균자본비용(WACC) | F2: 가중평균자본비용(WACC) | G2: 가중평균자본비용(WACC) | H2: 가중평균자본비용(WACC)
B4: 자기자본비용 | C4: 자기자본비용 | D4: 자기자본비용 | E4: 자기자본비용 | F4: 자기자본비용 | G4: 자기자본비용 | H4: 자기자본비용
B5: 무위험수익률 | C5: =가정!C30 -> 0.031 | E5: 산정방법 자기자본비용 = 무위험수익률 + 베타 × ERP + 국가위험프리미엄 공시상 금융기관차입금이 사실상 없으므로 타인자본 비중 5%는 관측 자본구조가 아닌 정상화 목표값입니다. WACC 입력값은 교육용 가정이며 실제 업무 시 최신 시장자료와 비교기업 베타 분석을 반영해야 합니다. | F5: 산정방법 자기자본비용 = 무위험수익률 + 베타 × ERP + 국가위험프리미엄 공시상 금융기관차입금이 사실상 없으므로 타인자본 비중 5%는 관측 자본구조가 아닌 정상화 목표값입니다. WACC 입력값은 교육용 가정이며 실제 업무 시 최신 시장자료와 비교기업 베타 분석을 반영해야 합니다. | G5: 산정방법 자기자본비용 = 무위험수익률 + 베타 × ERP + 국가위험프리미엄 공시상 금융기관차입금이 사실상 없으므로 타인자본 비중 5%는 관측 자본구조가 아닌 정상화 목표값입니다. WACC 입력값은 교육용 가정이며 실제 업무 시 최신 시장자료와 비교기업 베타 분석을 반영해야 합니다. | H5: 산정방법 자기자본비용 = 무위험수익률 + 베타 × ERP + 국가위험프리미엄 공시상 금융기관차입금이 사실상 없으므로 타인자본 비중 5%는 관측 자본구조가 아닌 정상화 목표값입니다. WACC 입력값은 교육용 가정이며 실제 업무 시 최신 시장자료와 비교기업 베타 분석을 반영해야 합니다.
